Workbook

Sheet 202609
A1: 2026년 9월 한탄강 수계 수질조사 결과
A2: 연번 | B2: 하천명 | C2: 시료번호 | D2: 주 소 | E2: TOC | F2: COD | G2: BOD | H2: SS | I2: T-N | J2: T-P | K2: 색도 | L2: 시료채취일 | M2: 요일
A3: 1 | B3: 1)한탄강 | C3: 한탄강1 | D3: 포천시 창수면 운산리 영로교 아래 | E3: 3.92 | F3: 7.3 | G3: 1.5 | H3: 1.4 | I3: 6.44 | J3: 0.02 | K3: 7 | L3: 46293 | M3: =TEXT(L3,"aaa") -> 월
A4: 2 | C4: 한탄강 연1 | D4: 연천군 전곡읍 신답리 1(영평천 합류전) | E4: 1.9 | G4: 1.6 | H4: 4.8 | I4: 4.553 | J4: 0.081 | K4: 17 | L4: 46275 | M4: =TEXT(L4,"aaa") -> 목
A5: 3 | C5: 한탄강 연2 | D5: 연천군 청산면 궁평리 561-1(영평천 합류후) | E5: 2 | G5: 2.2 | H5: 3.8 | I5: 4.481 | J5: 0.076 | K5: 16 | L5: 46275 | M5: =TEXT(L5,"aaa") -> 목
A6: 4 | C6: 한탄강 연4 | D6: 연천군 전곡읍 전곡리 681-2(세월교)_색도 목표지점 | E6: 2.4 | G6: 0.9 | H6: 2.6 | I6: 5.657 | J6: 0.07 | K6: 17 | L6: 46275 | M6: =TEXT(L6,"aaa") -> 목
A7: 5 | B7: 2)포천천 | C7: 포천천1 | D7: 포천시 소흘읍 무봉리 이동교리교 (포천천 상류,부인터사거리 뒤) | E7: 4.27 | G7: 1.9 | H7: 5.2 | I7: 2.679 | J7: 0.056 | K7: 9 | L7: 46293 | M7: =TEXT(L7,"aaa") -> 월
A8: 6 | C8: 포천천2 | D8: 포천시 신읍동 한내교 아래(실제 가스충전소 뒤 / 중류) | E8: 4.22 | F8: 5.2 | G8: 2.1 | H8: 5.7 | I8: 10.656 | J8: 0.14 | K8: 8 | L8: 46293 | M8: =TEXT(L8,"aaa") -> 월
A9: 7 | C9: 포천천3 | D9: 포천시 영중면 거사3리 농본교(포천천 하류) | E9: 4.18 | G9: 6 | H9: 27.6 | I9: 4.733 | J9: 0.042 | K9: 10 | L9: 46293 | M9: =TEXT(L9,"aaa") -> 월
A10: 8 | B10: 3)금현천 | C10: 금현천 | D10: 포천시 가산면 마산리 금현천교 아래(세창아파트 뒤) | E10: 4.09 | G10: 3.6 | H10: 76.8 | I10: 5.027 | J10: 0.017 | K10: 14 | L10: 46293 | M10: =TEXT(L10,"aaa") -> 월
A11: 9 | B11: 4)송우천 | C11: 송우천 | D11: 포천시 송우리 641-92(송우교 아래) | E11: 3.98 | G11: 2.3 | H11: 19.8 | I11: 3.593 | J11: 0.042 | K11: 11 | L11: 46293 | M11: =TEXT(L11,"aaa") -> 월
A12: 10 | B12: 5)영평천 | C12: 영평천1 | D12: 포천시 이동면 노곡리 낭유대교 아래(영평천 상류) | E12: 1.66 | F12: 3.7 | G12: 3.8 | H12: 34.4 | I12: 3.338 | J12: 0.043 | K12: 11 | L12: 46293 | M12: =TEXT(L12,"aaa") -> 월
A13: 11 | C13: 영평천2 | D13: 포천시 영중면 성동리 와룡교 아래(수입천 합류 후) | E13: 1.68 | G13: 2.9 | H13: 5.8 | I13: 4.54 | J13: 0.081 | K13: 15 | L13: 46293 | M13: =TEXT(L13,"aaa") -> 월
A14: 12 | C14: 영평천3 | D14: 포천시 영중면 영송리 영평교 아래(포천천 합류 후) | E14: 2.15 | G14: 3.3 | H14: 6.4 | I14: 4.941 | J14: 0.099 | K14: 18 | L14: 46293 | M14: =TEXT(L14,"aaa") -> 월
A15: 13 | C15: 영평천4 | D15: 포천시 창수면 오가리 오가교 아래(외북천 합류 후) | E15: 2.06 | G15: 3 | H15: 8.8 | I15: 4.772 | J15: 0.078 | K15: 22 | L15: 46293 | M15: =TEXT(L15,"aaa") -> 월
A16: 14 | C16: 영평천5 | D16: 포천시 창수면 고소성리 백의교(포천-연천 경계 / 영평천 하류) | E16: 2.15 | G16: 2.7 | H16: 11 | I16: 5.821 | J16: 0.114 | K16: 34 | L16: 46293 | M16: =TEXT(L16,"aaa") -> 월
A17: 15 | B17: 6)외북천 | C17: 외북천2 | D17: 포천시 영중면 영송리 통일교 아래(외북천 중류) | E17: 3.45 | G17: 3.8 | H17: 7 | I17: 6.836 | J17: 0.084 | K17: 35 | L17: 46293 | M17: =TEXT(L17,"aaa") -> 월
A18: 16 | C18: 외북천3 | D18: 포천시 영중면 영송리 두엄바이오 앞 (외북천 하류) | E18: 3.35 | G18: 4.8 | H18: 8.4 | I18: 6.293 | J18: 0.077 | K18: 32 | L18: 46293 | M18: =TEXT(L18,"aaa") -> 월
A19: 17 | B19: 7)수입천 | C19: 수입천 | D19: 포천시 일동면 사직리 1390-5(일이동처리장 입구) | E19: 1.7 | F19: 3.5 | G19: 3.3 | H19: 7.2 | I19: 6.15 | J19: 0.071 | K19: 31 | L19: 46293 | M19: =TEXT(L19,"aaa") -> 월
A20: 18 | B20: 8)신천 | C20: 신천1 | D20: 양주시 백석읍 오산리 137-2(신천-오산리_방성천 합류 전) | E20: 2.73 | G20: 1.8 | H20: 2.7 | I20: 12.8 | J20: 0.091 | K20: 8 | L20: 46294 | M20: =TEXT(L20,"aaa") -> 화
A21: 19 | C21: 신천5 | D21: 양주시 광적면 가납리 710(신천-우고천 합류 후) | E21: 3.48 | G21: 6.6 | H21: 26.4 | I21: 18.047 | J21: 0.074 | K21: 19 | L21: 46294 | M21: =TEXT(L21,"aaa") -> 화
A22: 20 | C22: 신천중류 | D22: 양주시 남면 상수리 104-39(입암천 합류 전) | E22: 7.6 | G22: 1.2 | H22: 1.4 | I22: 2.142 | J22: 0.026 | K22: 6 | L22: 46294 | M22: =TEXT(L22,"aaa") -> 화
A23: 21 | C23: 신천9 | D23: 양주시 은현면 운암리 60-15(은현교) | E23: 6.52 | G23: 1 | H23: 3.5 | I23: 1.999 | J23: 0.014 | K23: 3 | L23: 46294 | M23: =TEXT(L23,"aaa") -> 화
A24: 22 | C24: 용암교 | D24: 양주시 은현면 용암리 241-1(구 세월교) | E24: 5.95 | F24: 6.7 | G24: 3.3 | H24: 4.4 | I24: 7.035 | J24: 0.051 | K24: 12 | L24: 46294 | M24: =TEXT(L24,"aaa") -> 화
A25: 23 | C25: 신천11 | D25: 양주시 은현면 용암리 240-1(위생환경사업소앞) | E25: 5.88 | G25: 1.6 | H25: 18 | I25: 1.538 | J25: 0.04 | K25: 5 | L25: 46294 | M25: =TEXT(L25,"aaa") -> 화
A26: 24 | C26: 신천13 | D26: 동두천시 송내동 651-3(현대아이파크 앞) | E26: 4.6 | G26: 1.9 | H26: 6.5 | I26: 4.782 | J26: 0.164 | K26: 12 | L26: 46274 | M26: =TEXT(L26,"aaa") -> 수
A27: 25 | C27: 신천15 | D27: 동두천시 보산동 429-48 인근 진검다리 | E27: 4.9 | G27: 3 | H27: 13.8 | I27: 4.188 | J27: 0.017 | K27: 19 | L27: 46274 | M27: =TEXT(L27,"aaa") -> 수
A28: 26 | C28: 신천17 | D28: 동두천시 하봉암동 340-1 인근 | E28: 5.3 | G28: 3.9 | H28: 18.2 | I28: 4.169 | J28: 0.065 | K28: 20 | L28: 46274 | M28: =TEXT(L28,"aaa") -> 수
A29: 27 | C29: 신천17-2 | D29: 동두천시 하봉암동 327-1(하봉암교) | E29: 6.1 | G29: 3.5 | H29: 16.4 | I29: 4.871 | J29: 0.064 | K29: 33 | L29: 46274 | M29: =TEXT(L29,"aaa") -> 수
A30: 28 | C30: 신천18-1 | D30: 연천군 청산면 초성리 426, 초성교(시군경계) | E30: 6.6 | G30: 3.3 | H30: 19.6 | I30: 4.678 | J30: 0.051 | K30: 21 | L30: 46275 | M30: =TEXT(L30,"aaa") -> 목
A31: 29 | C31: 신천18 | D31: 연천군 청산면 초성리 142-5(신천교) | E31: 6.4 | G31: 3 | H31: 19.8 | I31: 4.521 | J31: 0.041 | K31: 20 | L31: 46275 | M31: =TEXT(L31,"aaa") -> 목
A32: 30 | C32: 신천20 | D32: 연천군 청산면 초성리 306-5(대전교) | E32: 6 | G32: 3 | H32: 24.2 | I32: 3.745 | J32: 0.038 | K32: 19 | L32: 46275 | M32: =TEXT(L32,"aaa") -> 목
A33: 31 | B33: 9)능안천 | C33: 능안천 | D33: 양주시 백석읍 방성리 205-12 | E33: 3.92 | G33: 1.9 | H33: 1.7 | I33: 13.962 | J33: 0.037 | K33: 12 | L33: 46294 | M33: =TEXT(L33,"aaa") -> 화
A34: 32 | B34: 10)효촌천 | C34: 효촌천 | D34: 양주시 남면 상수리 264 | E34: 29.35 | G34: 5 | H34: 13.2 | I34: 4.497 | J34: 0.135 | K34: 29 | L34: 46294 | M34: =TEXT(L34,"aaa") -> 화
A35: 33 | B35: 11)덕계천 | C35: 덕계천-하 | D35: 양주시 회정동 317-4 | E35: 2.93 | G35: 0.4 | H35: 0.6 | I35: 3.975 | J35: 0.019 | K35: 9 | L35: 46294 | M35: =TEXT(L35,"aaa") -> 화 | N35: 변경지점
A36: 34 | B36: 12)마개미천 | C36: 마개미천 | D36: 양주시 덕계동 169-17 | E36: 1.87 | G36: 1.2 | H36: 2.5 | I36: 3.279 | J36: 0.028 | K36: 16 | L36: 46294 | M36: =TEXT(L36,"aaa") -> 화 | N36: 신규지점
A37: 35 | B37: 13)회암천 | C37: 회암천_중 | D37: 양주시 옥정동로 율정초교 앞 | E37: 5.31 | G37: 2.8 | H37: 1.9 | I37: 8.889 | J37: 0.029 | K37: 9 | L37: 46294 | M37: =TEXT(L37,"aaa") -> 화
A38: 36 | B38: 14)청담천 | C38: 청담천 | D38: 양주시 고암동 211-1 | E38: 2.95 | G38: 0.8 | H38: 2.2 | I38: 2.619 | J38: 0.027 | K38: 16 | L38: 46294 | M38: =TEXT(L38,"aaa") -> 화
A39: 37 | B39: 15)상패천 | C39: 상패천 | D39: 동두천시 상패동 307-7 인근 (강변교 아래) (신천 합류 전) | E39: 3.7 | G39: 5.9 | H39: 15.4 | I39: 0.696 | J39: 0.062 | K39: 17 | L39: 46274 | M39: =TEXT(L39,"aaa") -> 수

Sheet 202608
A1: 2026년 8월 한탄강 수계 수질조사 결과
A2: 연번 | B2: 하천명 | C2: 시료번호 | D2: 주 소 | E2: TOC | F2: COD | G2: BOD | H2: SS | I2: T-N | J2: T-P | K2: 색도 | L2: 시료채취일 | M2: 요일
A3: 1 | B3: 1)한탄강 | C3: 한탄강1 | D3: 포천시 창수면 운산리 영로교 아래 | E3: 2.4 | F3: 3.8 | G3: 1.5 | H3: 6 | I3: 4.495 | J3: 0.058 | K3: 11 | L3: 46258 | M3: =TEXT(L3,"aaa") -> 월
A4: 2 | C4: 한탄강 연1 | D4: 연천군 전곡읍 신답리 1(영평천 합류전) | E4: 2.1 | G4: 1.2 | H4: 3.7 | I4: 1.42 | J4: 0.01 | K4: 6 | L4: 46245 | M4: =TEXT(L4,"aaa") -> 화
A5: 3 | C5: 한탄강 연2 | D5: 연천군 청산면 궁평리 561-1(영평천 합류후) | E5: 2.7 | G5: 1.4 | H5: 4.3 | I5: 2.199 | J5: 0.012 | K5: 7 | L5: 46245 | M5: =TEXT(L5,"aaa") -> 화
A6: 4 | C6: 한탄강 연4 | D6: 연천군 전곡읍 전곡리 681-2(세월교)_색도 목표지점 | E6: 3 | G6: 1.4 | H6: 5.7 | I6: 2.067 | J6: 0.011 | K6: 12 | L6: 46245 | M6: =TEXT(L6,"aaa") -> 화
A7: 5 | B7: 2)포천천 | C7: 포천천1 | D7: 포천시 소흘읍 무봉리 이동교리교 (포천천 상류,부인터사거리 뒤) | E7: 2.9 | G7: 1.1 | H7: 2.6 | I7: 3.848 | J7: 0.1 | K7: 10 | L7: 46258 | M7: =TEXT(L7,"aaa") -> 월
A8: 6 | C8: 포천천2 | D8: 포천시 신읍동 한내교 아래(실제 가스충전소 뒤 / 중류) | E8: 2.9 | F8: 3.7 | G8: 1.4 | H8: 3.1 | I8: 3.788 | J8: 0.096 | K8: 14 | L8: 46258 | M8: =TEXT(L8,"aaa") -> 월
A9: 7 | C9: 포천천3 | D9: 포천시 영중면 거사3리 농본교(포천천 하류) | E9: 3 | G9: 1.5 | H9: 2.9 | I9: 3.728 | J9: 0.098 | K9: 12 | L9: 46258 | M9: =TEXT(L9,"aaa") -> 월
A10: 8 | B10: 3)금현천 | C10: 금현천 | D10: 포천시 가산면 마산리 금현천교 아래(세창아파트 뒤) | E10: 3.4 | G10: 1.2 | H10: 1.5 | I10: 6.713 | J10: 0.028 | K10: 12 | L10: 46258 | M10: =TEXT(L10,"aaa") -> 월
A11: 9 | B11: 4)송우천 | C11: 송우천 | D11: 포천시 송우리 641-92(송우교 아래) | E11: 3.4 | G11: 1.3 | H11: 3 | I11: 6.702 | J11: 0.027 | K11: 11 | L11: 46258 | M11: =TEXT(L11,"aaa") -> 월
A12: 10 | B12: 5)영평천 | C12: 영평천1 | D12: 포천시 이동면 노곡리 낭유대교 아래(영평천 상류) | E12: 3 | F12: 3.6 | G12: 1.3 | H12: 3 | I12: 3.852 | J12: 0.098 | K12: 8 | L12: 46258 | M12: =TEXT(L12,"aaa") -> 월
A13: 11 | C13: 영평천2 | D13: 포천시 영중면 성동리 와룡교 아래(수입천 합류 후) | E13: 2.5 | G13: 1.1 | H13: 5.7 | I13: 4.421 | J13: 0.055 | K13: 10 | L13: 46258 | M13: =TEXT(L13,"aaa") -> 월
A14: 12 | C14: 영평천3 | D14: 포천시 영중면 영송리 영평교 아래(포천천 합류 후) | E14: 2.5 | G14: 1.2 | H14: 6.1 | I14: 4.42 | J14: 0.057 | K14: 10 | L14: 46258 | M14: =TEXT(L14,"aaa") -> 월
A15: 13 | C15: 영평천4 | D15: 포천시 창수면 오가리 오가교 아래(외북천 합류 후) | E15: 3.4 | G15: 1.3 | H15: 1.5 | I15: 6.671 | J15: 0.025 | K15: 11 | L15: 46258 | M15: =TEXT(L15,"aaa") -> 월
A16: 14 | C16: 영평천5 | D16: 포천시 창수면 고소성리 백의교(포천-연천 경계 / 영평천 하류) | E16: 3.4 | G16: 1.3 | H16: 1.4 | I16: 6.637 | J16: 0.025 | K16: 12 | L16: 46258 | M16: =TEXT(L16,"aaa") -> 월
A17: 15 | B17: 6)외북천 | C17: 외북천2 | D17: 포천시 영중면 영송리 통일교 아래(외북천 중류) | E17: 5.1 | G17: 1.9 | H17: 8.6 | I17: 8.081 | J17: 0.821 | K17: 23 | L17: 46258 | M17: =TEXT(L17,"aaa") -> 월
A18: 16 | C18: 외북천3 | D18: 포천시 영중면 영송리 두엄바이오 앞 (외북천 하류) | E18: 5 | G18: 2.1 | H18: 18 | I18: 8.096 | J18: 0.827 | K18: 21 | L18: 46258 | M18: =TEXT(L18,"aaa") -> 월
A19: 17 | B19: 7)수입천 | C19: 수입천 | D19: 포천시 일동면 사직리 1390-5(일이동처리장 입구) | E19: 2.5 | F19: 3.5 | G19: 1.6 | H19: 6.4 | I19: 4.432 | J19: 0.058 | K19: 11 | L19: 46258 | M19: =TEXT(L19,"aaa") -> 월
A20: 18 | B20: 8)신천 | C20: 신천1 | D20: 양주시 백석읍 오산리 137-2(신천-오산리_방성천 합류 전) | E20: 2.8 | G20: 1.5 | H20: 1.1 | I20: 2.416 | J20: 0.036 | K20: 7 | L20: 46246 | M20: =TEXT(L20,"aaa") -> 수
A21: 19 | C21: 신천5 | D21: 양주시 광적면 가납리 710(신천-우고천 합류 후) | E21: 3.4 | G21: 1.5 | H21: 2.8 | I21: 3.708 | J21: 0.107 | K21: 9 | L21: 46246 | M21: =TEXT(L21,"aaa") -> 수
A22: 20 | C22: 신천중류 | D22: 양주시 남면 상수리 104-39(입암천 합류 전) | E22: 5.4 | G22: 4.1 | H22: 4.8 | I22: 5.077 | J22: 0.084 | K22: 22 | L22: 46246 | M22: =TEXT(L22,"aaa") -> 수
A23: 21 | C23: 신천9 | D23: 양주시 은현면 운암리 60-15(은현교) | E23: 5.7 | G23: 2.3 | H23: 6.2 | I23: 4.428 | J23: 0.084 | K23: 16 | L23: 46246 | M23: =TEXT(L23,"aaa") -> 수
A24: 22 | C24: 용암교 | D24: 양주시 은현면 용암리 241-1(구 세월교) | E24: 1.8 | F24: 3.6 | G24: 1.6 | H24: 7.8 | I24: 4.735 | J24: 0.066 | K24: 16 | L24: 46246 | M24: =TEXT(L24,"aaa") -> 수
A25: 23 | C25: 신천11 | D25: 양주시 은현면 용암리 240-1(위생환경사업소앞) | E25: 5.4 | G25: 3.6 | H25: 8.8 | I25: 5.038 | J25: 0.07 | K25: 12 | L25: 46246 | M25: =TEXT(L25,"aaa") -> 수
A26: 24 | C26: 신천13 | D26: 동두천시 송내동 651-3(현대아이파크 앞) | E26: 5.5 | G26: 2.3 | H26: 13.6 | I26: 3.493 | J26: 0.019 | K26: 12 | L26: 46247 | M26: =TEXT(L26,"aaa") -> 목
A27: 25 | C27: 신천15 | D27: 동두천시 보산동 429-48 인근 진검다리 | E27: 6.9 | G27: 3 | H27: 13.8 | I27: 4.188 | J27: 0.017 | K27: 19 | L27: 46247 | M27: =TEXT(L27,"aaa") -> 목
A28: 26 | C28: 신천17 | D28: 동두천시 하봉암동 340-1 인근 | E28: 6.9 | G28: 3.9 | H28: 18.2 | I28: 4.169 | J28: 0.065 | K28: 20 | L28: 46247 | M28: =TEXT(L28,"aaa") -> 목
A29: 27 | C29: 신천17-2 | D29: 동두천시 하봉암동 327-1(하봉암교) | E29: 7.5 | G29: 3.5 | H29: 16.4 | I29: 4.871 | J29: 0.064 | K29: 33 | L29: 46247 | M29: =TEXT(L29,"aaa") -> 목
A30: 28 | C30: 신천18-1 | D30: 연천군 청산면 초성리 426, 초성교(시군경계) | E30: 5.6 | G30: 3.3 | H30: 19.6 | I30: 4.678 | J30: 0.051 | K30: 21 | L30: 46245 | M30: =TEXT(L30,"aaa") -> 화
A31: 29 | C31: 신천18 | D31: 연천군 청산면 초성리 142-5(신천교) | E31: 5.4 | G31: 3 | H31: 19.8 | I31: 4.521 | J31: 0.041 | K31: 20 | L31: 46245 | M31: =TEXT(L31,"aaa") -> 화
A32: 30 | C32: 신천20 | D32: 연천군 청산면 초성리 306-5(대전교) | E32: 5.7 | G32: 3 | H32: 24.2 | I32: 3.745 | J32: 0.038 | K32: 19 | L32: 46245 | M32: =TEXT(L32,"aaa") -> 화
A33: 31 | B33: 9)능안천 | C33: 능안천 | D33: 양주시 백석읍 방성리 205-12 | E33: 1.3 | G33: 1.9 | H33: 1.7 | I33: 13.962 | J33: 0.037 | K33: 12 | L33: 46246 | M33: =TEXT(L33,"aaa") -> 수
A34: 32 | B34: 10)효촌천 | C34: 효촌천 | D34: 양주시 남면 상수리 264 | E34: 7.8 | G34: 5 | H34: 13.2 | I34: 4.497 | J34: 0.135 | K34: 29 | L34: 46246 | M34: =TEXT(L34,"aaa") -> 수
A35: 33 | B35: 11)덕계천 | C35: 덕계천-하 | D35: 양주시 회정동 317-4 | E35: 0.9 | G35: 0.4 | H35: 0.6 | I35: 3.975 | J35: 0.019 | K35: 9 | L35: 46246 | M35: =TEXT(L35,"aaa") -> 수 | N35: 변경지점
A36: 34 | B36: 12)마개미천 | C36: 마개미천 | D36: 양주시 덕계동 169-17 | E36: 0.7 | G36: 1.2 | H36: 2.5 | I36: 3.279 | J36: 0.028 | K36: 16 | L36: 46246 | M36: =TEXT(L36,"aaa") -> 수 | N36: 신규지점
A37: 35 | B37: 13)회암천 | C37: 회암천_중 | D37: 양주시 옥정동로 율정초교 앞 | E37: 3.7 | G37: 2.8 | H37: 1.9 | I37: 8.889 | J37: 0.029 | K37: 9 | L37: 46246 | M37: =TEXT(L37,"aaa") -> 수
A38: 36 | B38: 14)청담천 | C38: 청담천 | D38: 양주시 고암동 211-1 | E38: 1.2 | G38: 0.8 | H38: 2.2 | I38: 2.619 | J38: 0.027 | K38: 16 | L38: 46246 | M38: =TEXT(L38,"aaa") -> 수
A39: 37 | B39: 15)상패천 | C39: 상패천 | D39: 동두천시 상패동 307-7 인근 (강변교 아래) (신천 합류 전) | E39: 6.6 | G39: 5.9 | H39: 15.4 | I39: 0.696 | J39: 0.062 | K39: 17 | L39: 46247 | M39: =TEXT(L39,"aaa") -> 목

Sheet 202607
A1: 2026년 7월 한탄강 수계 수질조사 결과
A2: 연번 | B2: 하천명 | C2: 시료번호 | D2: 주 소 | E2: TOC | F2: COD | G2: BOD | H2: SS | I2: T-N | J2: T-P | K2: 색도 | L2: 시료채취일 | M2: 요일
A3: 1 | B3: 1)한탄강 | C3: 한탄강1 | D3: 포천시 창수면 운산리 영로교 아래 | E3: 2.93 | F3: 4.3 | G3: 1.1 | H3: 3.1 | I3: 5.696 | J3: 0.05 | K3: 12 | L3: 46232 | M3: =TEXT(L3,"aaa") -> 수
A4: 2 | C4: 한탄강 연1 | D4: 연천군 전곡읍 신답리 1(영평천 합류전) | E4: 1.93 | G4: 1.5 | H4: 18.8 | I4: 1.865 | J4: 0.044 | K4: 13 | L4: 46232 | M4: =TEXT(L4,"aaa") -> 수
A5: 3 | C5: 한탄강 연2 | D5: 연천군 청산면 궁평리 561-1(영평천 합류후) | E5: 1.87 | G5: 1.4 | H5: 19.5 | I5: 1.863 | J5: 0.044 | K5: 15 | L5: 46232 | M5: =TEXT(L5,"aaa") -> 수
A6: 4 | C6: 한탄강 연4 | D6: 연천군 전곡읍 전곡리 681-2(세월교)_색도 목표지점 | E6: 1.83 | G6: 1.5 | H6: 18.7 | I6: 2.338 | J6: 0.047 | K6: 15 | L6: 46232 | M6: =TEXT(L6,"aaa") -> 수
A7: 5 | B7: 2)포천천 | C7: 포천천1 | D7: 포천시 소흘읍 무봉리 이동교리교 (포천천 상류,부인터사거리 뒤) | E7: 2.4 | G7: 0.7 | H7: 2.2 | I7: 4.574 | J7: 0.076 | K7: 9 | L7: 46232 | M7: =TEXT(L7,"aaa") -> 수
A8: 6 | C8: 포천천2 | D8: 포천시 신읍동 한내교 아래(실제 가스충전소 뒤 / 중류) | E8: 2.48 | F8: 3.3 | G8: 1.1 | H8: 2.7 | I8: 4.308 | J8: 0.073 | K8: 14 | L8: 46232 | M8: =TEXT(L8,"aaa") -> 수
A9: 7 | C9: 포천천3 | D9: 포천시 영중면 거사3리 농본교(포천천 하류) | E9: 2.5 | G9: 0.7 | H9: 2.3 | I9: 4.54 | J9: 0.075 | K9: 11 | L9: 46232 | M9: =TEXT(L9,"aaa") -> 수
A10: 8 | B10: 3)금현천 | C10: 금현천 | D10: 포천시 가산면 마산리 금현천교 아래(세창아파트 뒤) | E10: 2.9 | G10: 0.7 | H10: 2.7 | I10: 5.71 | J10: 0.05 | K10: 9 | L10: 46232 | M10: =TEXT(L10,"aaa") -> 수
A11: 9 | B11: 4)송우천 | C11: 송우천 | D11: 포천시 송우리 641-92(송우교 아래) | E11: 2.9 | G11: 0.6 | H11: 2.4 | I11: 5.841 | J11: 0.052 | K11: 10 | L11: 46232 | M11: =TEXT(L11,"aaa") -> 수
A12: 10 | B12: 5)영평천 | C12: 영평천1 | D12: 포천시 이동면 노곡리 낭유대교 아래(영평천 상류) | E12: 2.2 | F12: 4 | G12: 1.5 | H12: 2.3 | I12: 6.623 | J12: 0.064 | K12: 8 | L12: 46232 | M12: =TEXT(L12,"aaa") -> 수
A13: 11 | C13: 영평천2 | D13: 포천시 영중면 성동리 와룡교 아래(수입천 합류 후) | E13: 2.1 | G13: 0.7 | H13: 2.2 | I13: 6.919 | J13: 0.064 | K13: 21 | L13: 46232 | M13: =TEXT(L13,"aaa") -> 수
A14: 12 | C14: 영평천3 | D14: 포천시 영중면 영송리 영평교 아래(포천천 합류 후) | E14: 2 | G14: 0.7 | H14: 1 | I14: 4.462 | J14: 0.039 | K14: 6 | L14: 46232 | M14: =TEXT(L14,"aaa") -> 수
A15: 13 | C15: 영평천4 | D15: 포천시 창수면 오가리 오가교 아래(외북천 합류 후) | E15: 2 | G15: 0.5 | H15: 1.1 | I15: 4.569 | J15: 0.039 | K15: 7 | L15: 46232 | M15: =TEXT(L15,"aaa") -> 수
A16: 14 | C16: 영평천5 | D16: 포천시 창수면 고소성리 백의교(포천-연천 경계 / 영평천 하류) | E16: 2 | G16: 0.6 | H16: 0.7 | I16: 4.607 | J16: 0.039 | K16: 8 | L16: 46232 | M16: =TEXT(L16,"aaa") -> 수
A17: 15 | B17: 6)외북천 | C17: 외북천2 | D17: 포천시 영중면 영송리 통일교 아래(외북천 중류) | E17: 3.7 | G17: 0.9 | H17: 8.5 | I17: 8.996 | J17: 0.121 | K17: 15 | L17: 46232 | M17: =TEXT(L17,"aaa") -> 수
A18: 16 | C18: 외북천3 | D18: 포천시 영중면 영송리 두엄바이오 앞 (외북천 하류) | E18: 3.7 | G18: 0.9 | H18: 7.9 | I18: 9.146 | J18: 0.128 | K18: 18 | L18: 46232 | M18: =TEXT(L18,"aaa") -> 수
A19: 17 | B19: 7)수입천 | C19: 수입천 | D19: 포천시 일동면 사직리 1390-5(일이동처리장 입구) | E19: 2.14 | F19: 2.7 | G19: 1 | H19: 2.3 | I19: 6.82 | J19: 0.064 | K19: 10 | L19: 46232 | M19: =TEXT(L19,"aaa") -> 수
A20: 18 | B20: 8)신천 | C20: 신천1 | D20: 양주시 백석읍 오산리 137-2(신천-오산리_방성천 합류 전) | E20: 2.8 | G20: 1.8 | H20: 2.3 | I20: 3.111 | J20: 0.066 | K20: 9 | L20: 46230 | M20: =TEXT(L20,"aaa") -> 월
A21: 19 | C21: 신천5 | D21: 양주시 광적면 가납리 710(신천-우고천 합류 후) | E21: 3.3 | G21: 1.8 | H21: 5.7 | I21: 3.315 | J21: 0.11 | K21: 12 | L21: 46230 | M21: =TEXT(L21,"aaa") -> 월
A22: 20 | C22: 신천중류 | D22: 양주시 남면 상수리 104-39(입암천 합류 전) | E22: 4.2 | G22: 2.4 | H22: 7.1 | I22: 4.595 | J22: 0.102 | K22: 13 | L22: 46230 | M22: =TEXT(L22,"aaa") -> 월
A23: 21 | C23: 신천9 | D23: 양주시 은현면 운암리 60-15(은현교) | E23: 3.7 | G23: 1.9 | H23: 6.5 | I23: 4.822 | J23: 0.119 | K23: 11 | L23: 46230 | M23: =TEXT(L23,"aaa") -> 월
A24: 22 | C24: 용암교 | D24: 양주시 은현면 용암리 241-1(구 세월교) | E24: 2.9 | F24: 5.8 | G24: 0.9 | H24: 17.2 | I24: 4.13 | J24: 0.138 | K24: 15 | L24: 46230 | M24: =TEXT(L24,"aaa") -> 월
A25: 23 | C25: 신천11 | D25: 양주시 은현면 용암리 240-1(위생환경사업소앞) | E25: 3.5 | G25: 2.2 | H25: 8 | I25: 4.093 | J25: 0.102 | K25: 9 | L25: 46230 | M25: =TEXT(L25,"aaa") -> 월
A26: 24 | C26: 신천13 | D26: 동두천시 송내동 651-3(현대아이파크 앞) | E26: 3.9 | G26: 4.3 | H26: 9.7 | I26: 4.252 | J26: 0.087 | K26: 24 | L26: 46217 | M26: =TEXT(L26,"aaa") -> 화
A27: 25 | C27: 신천15 | D27: 동두천시 보산동 429-48 인근 진검다리 | E27: 5 | G27: 3.7 | H27: 7.2 | I27: 5.619 | J27: 0.118 | K27: 20 | L27: 46217 | M27: =TEXT(L27,"aaa") -> 화
A28: 26 | C28: 신천17 | D28: 동두천시 하봉암동 340-1 인근 | E28: 4.2 | G28: 3.4 | H28: 12 | I28: 4.93 | J28: 0.091 | K28: 16 | L28: 46217 | M28: =TEXT(L28,"aaa") -> 화
A29: 27 | C29: 신천17-2 | D29: 동두천시 하봉암동 327-1(하봉암교) | E29: 4.6 | G29: 4 | H29: 16.5 | I29: 5.418 | J29: 0.106 | K29: 19 | L29: 46217 | M29: =TEXT(L29,"aaa") -> 화
A30: 28 | C30: 신천18-1 | D30: 연천군 청산면 초성리 426, 초성교(시군경계) | E30: 4.09 | G30: 2.9 | H30: 4.1 | I30: 4.987 | J30: 0.084 | K30: 15 | L30: 46232 | M30: =TEXT(L30,"aaa") -> 수
A31: 29 | C31: 신천18 | D31: 연천군 청산면 초성리 142-5(신천교) | E31: 3.99 | G31: 2.1 | H31: 5.4 | I31: 5.039 | J31: 0.077 | K31: 17 | L31: 46232 | M31: =TEXT(L31,"aaa") -> 수
A32: 30 | C32: 신천20 | D32: 연천군 청산면 초성리 306-5(대전교) | E32: 3.85 | G32: 2.2 | H32: 3.2 | I32: 4.955 | J32: 0.074 | K32: 18 | L32: 46232 | M32: =TEXT(L32,"aaa") -> 수
A33: 31 | B33: 9)능안천 | C33: 능안천 | D33: 양주시 백석읍 방성리 205-12 | E33: 4.4 | G33: 1.9 | H33: 4.1 | I33: 4.032 | J33: 0.098 | K33: 18 | L33: 46230 | M33: =TEXT(L33,"aaa") -> 월
A34: 32 | B34: 10)효촌천 | C34: 효촌천 | D34: 양주시 남면 상수리 264 | E34: 6.1 | G34: 2.9 | H34: 9 | I34: 4.737 | J34: 0.121 | K34: 34 | L34: 46230 | M34: =TEXT(L34,"aaa") -> 월
A35: 33 | B35: 11)덕계천 | C35: 덕계천-하 | D35: 양주시 회정동 317-4 | E35: 3.2 | G35: 1.4 | H35: 5.6 | I35: 2.587 | J35: 0.023 | K35: 23 | L35: 46230 | M35: =TEXT(L35,"aaa") -> 월 | N35: 변경지점
A36: 34 | B36: 12)마개미천 | C36: 마개미천 | D36: 양주시 덕계동 169-17 | E36: 3.8 | G36: 1.2 | H36: 15.6 | I36: 3.144 | J36: 0.058 | K36: 5 | L36: 46230 | M36: =TEXT(L36,"aaa") -> 월 | N36: 신규지점
A37: 35 | B37: 13)회암천 | C37: 회암천_중 | D37: 양주시 옥정동로 율정초교 앞 | E37: 3.4 | G37: 1.2 | H37: 11.6 | I37: 5.666 | J37: 0.055 | K37: 8 | L37: 46230 | M37: =TEXT(L37,"aaa") -> 월
A38: 36 | B38: 14)청담천 | C38: 청담천 | D38: 양주시 고암동 211-1 | E38: 2.9 | G38: 1.3 | H38: 4.5 | I38: 2.894 | J38: 0.058 | K38: 8 | L38: 46230 | M38: =TEXT(L38,"aaa") -> 월
A39: 37 | B39: 15)상패천 | C39: 상패천 | D39: 동두천시 상패동 307-7 인근 (강변교 아래) (신천 합류 전) | E39: 3.9 | G39: 3.8 | H39: 10.3 | I39: 3.817 | J39: 0.114 | K39: 13 | L39: 46217 | M39: =TEXT(L39,"aaa") -> 화

Sheet 202606
A1: 2026년 6월 한탄강 수계 수질조사 결과
A2: 연번 | B2: 하천명 | C2: 시료번호 | D2: 주 소 | E2: TOC | F2: COD | G2: BOD | H2: SS | I2: T-N | J2: T-P | K2: 색도 | L2: 시료채취일 | M2: 요일
A3: 1 | B3: 1)한탄강 | C3: 한탄강1 | D3: 포천시 창수면 운산리 영로교 아래 | E3: 2.9 | F3: 5.6 | G3: 2.3 | H3: 9.6 | I3: 1.671 | J3: 0.083 | K3: 40 | L3: 46182 | M3: =TEXT(L3,"aaa") -> 화
A4: 2 | C4: 한탄강 연1 | D4: 연천군 전곡읍 신답리 1(영평천 합류전) | E4: 2.8 | G4: 1.7 | H4: 13.4 | I4: 2.109 | J4: 0.049 | K4: 41 | L4: 46182 | M4: =TEXT(L4,"aaa") -> 화
A5: 3 | C5: 한탄강 연2 | D5: 연천군 청산면 궁평리 561-1(영평천 합류후) | E5: 2.9 | G5: 1.3 | H5: 12.2 | I5: 2.025 | J5: 0.032 | K5: 41 | L5: 46182 | M5: =TEXT(L5,"aaa") -> 화
A6: 4 | C6: 한탄강 연4 | D6: 연천군 전곡읍 전곡리 681-2(세월교)_색도 목표지점 | E6: 3.5 | G6: 2.1 | H6: 11.8 | I6: 1.995 | J6: 0.048 | K6: 48 | L6: 46182 | M6: =TEXT(L6,"aaa") -> 화
A7: 5 | B7: 2)포천천 | C7: 포천천1 | D7: 포천시 소흘읍 무봉리 이동교리교 (포천천 상류,부인터사거리 뒤) | E7: 3.6 | G7: 3.4 | H7: 9.4 | I7: 1.489 | J7: 0.032 | K7: 44 | L7: 46182 | M7: =TEXT(L7,"aaa") -> 화
A8: 6 | C8: 포천천2 | D8: 포천시 신읍동 한내교 아래(실제 가스충전소 뒤 / 중류) | E8: 3.6 | F8: 5.6 | G8: 3 | H8: 9.6 | I8: 1.685 | J8: 0.083 | K8: 38 | L8: 46182 | M8: =TEXT(L8,"aaa") -> 화
A9: 7 | C9: 포천천3 | D9: 포천시 영중면 거사3리 농본교(포천천 하류) | E9: 3.7 | G9: 2.4 | H9: 10.4 | I9: 1.678 | J9: 0.072 | K9: 40 | L9: 46182 | M9: =TEXT(L9,"aaa") -> 화
A10: 8 | B10: 3)금현천 | C10: 금현천 | D10: 포천시 가산면 마산리 금현천교 아래(세창아파트 뒤) | E10: 3.5 | G10: 3.5 | H10: 1.2 | I10: 3.858 | J10: 0.034 | K10: 58 | L10: 46182 | M10: =TEXT(L10,"aaa") -> 화
A11: 9 | B11: 4)송우천 | C11: 송우천 | D11: 포천시 송우리 641-92(송우교 아래) | E11: 3.6 | G11: 2 | H11: 0.8 | I11: 3.733 | J11: 0.035 | K11: 44 | L11: 46182 | M11: =TEXT(L11,"aaa") -> 화
A12: 10 | B12: 5)영평천 | C12: 영평천1 | D12: 포천시 이동면 노곡리 낭유대교 아래(영평천 상류) | E12: 1.9 | F12: 3.7 | G12: 1.1 | H12: 5.3 | I12: 5.03 | J12: 0.081 | K12: 23 | L12: 46182 | M12: =TEXT(L12,"aaa") -> 화
A13: 11 | C13: 영평천2 | D13: 포천시 영중면 성동리 와룡교 아래(수입천 합류 후) | E13: 1.9 | G13: 2.1 | H13: 10 | I13: 5.068 | J13: 0.083 | K13: 26 | L13: 46182 | M13: =TEXT(L13,"aaa") -> 화
A14: 12 | C14: 영평천3 | D14: 포천시 영중면 영송리 영평교 아래(포천천 합류 후) | E14: 2.1 | G14: 1.1 | H14: 5.1 | I14: 4.403 | J14: 0.04 | K14: 35 | L14: 46182 | M14: =TEXT(L14,"aaa") -> 화
A15: 13 | C15: 영평천4 | D15: 포천시 창수면 오가리 오가교 아래(외북천 합류 후) | E15: 2.1 | G15: 1.1 | H15: 6.6 | I15: 4.189 | J15: 0.035 | K15: 39 | L15: 46182 | M15: =TEXT(L15,"aaa") -> 화
A16: 14 | C16: 영평천5 | D16: 포천시 창수면 고소성리 백의교(포천-연천 경계 / 영평천 하류) | E16: 2.1 | G16: 1.9 | H16: 5.7 | I16: 4.19 | J16: 0.03 | K16: 32 | L16: 46182 | M16: =TEXT(L16,"aaa") -> 화
A17: 15 | B17: 6)외북천 | C17: 외북천2 | D17: 포천시 영중면 영송리 통일교 아래(외북천 중류) | E17: 4.9 | G17: 4 | H17: 6.1 | I17: 17.018 | J17: 0.08 | K17: 76 | L17: 46182 | M17: =TEXT(L17,"aaa") -> 화
A18: 16 | C18: 외북천3 | D18: 포천시 영중면 영송리 두엄바이오 앞 (외북천 하류) | E18: 4.7 | G18: 5.1 | H18: 22.8 | I18: 16.22 | J18: 0.085 | K18: 85 | L18: 46182 | M18: =TEXT(L18,"aaa") -> 화
A19: 17 | B19: 7)수입천 | C19: 수입천 | D19: 포천시 일동면 사직리 1390-5(일이동처리장 입구) | E19: 1.9 | F19: 3.8 | G19: 1.9 | H19: 17.9 | I19: 5.129 | J19: 0.088 | K19: 28 | L19: 46182 | M19: =TEXT(L19,"aaa") -> 화
A20: 18 | B20: 8)신천 | C20: 신천1 | D20: 양주시 백석읍 오산리 137-2(신천-오산리_방성천 합류 전) | E20: 3.4 | G20: 3.6 | H20: 4.6 | I20: 1.013 | J20: 0.089 | K20: 48 | L20: 46185 | M20: =TEXT(L20,"aaa") -> 금
A21: 19 | C21: 신천5 | D21: 양주시 광적면 가납리 710(신천-우고천 합류 후) | E21: 4 | G21: 4.5 | H21: 10.6 | I21: 17.856 | J21: 0.213 | K21: 42 | L21: 46185 | M21: =TEXT(L21,"aaa") -> 금
A22: 20 | C22: 신천중류 | D22: 양주시 남면 상수리 104-39(입암천 합류 전) | E22: 4.2 | G22: 3.9 | H22: 13.2 | I22: 4.053 | J22: 0.075 | K22: 44 | L22: 46185 | M22: =TEXT(L22,"aaa") -> 금
A23: 21 | C23: 신천9 | D23: 양주시 은현면 운암리 60-15(은현교) | E23: 4.5 | G23: 4.8 | H23: 12 | I23: 4.916 | J23: 0.079 | K23: 47 | L23: 46185 | M23: =TEXT(L23,"aaa") -> 금
A24: 22 | C24: 용암교 | D24: 양주시 은현면 용암리 241-1(구 세월교) | E24: 3.5 | F24: 6.8 | G24: 3.8 | H24: 15.8 | I24: 1.549 | J24: 0.01 | K24: 48 | L24: 46185 | M24: =TEXT(L24,"aaa") -> 금
A25: 23 | C25: 신천11 | D25: 양주시 은현면 용암리 240-1(위생환경사업소앞) | E25: 3.7 | G25: 3.4 | H25: 18.2 | I25: 3.116 | J25: 0.039 | K25: 37 | L25: 46185 | M25: =TEXT(L25,"aaa") -> 금
A26: 24 | C26: 신천13 | D26: 동두천시 송내동 651-3(현대아이파크 앞) | E26: 3.3 | G26: 4.4 | H26: 15.8 | I26: 4.766 | J26: 0.076 | K26: 35 | L26: 46183 | M26: =TEXT(L26,"aaa") -> 수
A27: 25 | C27: 신천15 | D27: 동두천시 보산동 429-48 인근 진검다리 | E27: 3.9 | G27: 4.5 | H27: 14.4 | I27: 6.28 | J27: 0.062 | K27: 55 | L27: 46183 | M27: =TEXT(L27,"aaa") -> 수
A28: 26 | C28: 신천17 | D28: 동두천시 하봉암동 340-1 인근 | E28: 4.2 | G28: 5.7 | H28: 35.8 | I28: 6.38 | J28: 0.085 | K28: 61 | L28: 46183 | M28: =TEXT(L28,"aaa") -> 수
A29: 27 | C29: 신천17-2 | D29: 동두천시 하봉암동 327-1(하봉암교) | E29: 5.1 | G29: 4.6 | H29: 15.2 | I29: 6.842 | J29: 0.102 | K29: 91 | L29: 46183 | M29: =TEXT(L29,"aaa") -> 수
A30: 28 | C30: 신천18-1 | D30: 연천군 청산면 초성리 426, 초성교(시군경계) | E30: 4.9 | G30: 1.2 | H30: 14.2 | I30: 7.473 | J30: 0.089 | K30: 65 | L30: 46182 | M30: =TEXT(L30,"aaa") -> 화
A31: 29 | C31: 신천18 | D31: 연천군 청산면 초성리 142-5(신천교) | E31: 4.8 | G31: 1.8 | H31: 15.4 | I31: 7.017 | J31: 0.091 | K31: 64 | L31: 46182 | M31: =TEXT(L31,"aaa") -> 화
A32: 30 | C32: 신천20 | D32: 연천군 청산면 초성리 306-5(대전교) | E32: 4.4 | G32: 1.5 | H32: 14.6 | I32: 5.755 | J32: 0.064 | K32: 64 | L32: 46182 | M32: =TEXT(L32,"aaa") -> 화
A33: 31 | B33: 9)능안천 | C33: 능안천 | D33: 양주시 백석읍 방성리 205-12 | E33: 4.6 | G33: 4.7 | H33: 9.8 | I33: 49.401 | J33: 0.032 | K33: 39 | L33: 46185 | M33: =TEXT(L33,"aaa") -> 금
A34: 32 | B34: 10)효촌천 | C34: 효촌천 | D34: 양주시 남면 상수리 264 | E34: 5 | G34: 5.2 | H34: 11.6 | I34: 2.378 | J34: 0.071 | K34: 41 | L34: 46185 | M34: =TEXT(L34,"aaa") -> 금
A35: 33 | B35: 11)덕계천 | C35: 덕계천-하 | D35: 양주시 회정동 317-4 | E35: 2 | G35: 2 | H35: 6.8 | I35: 1.385 | J35: 0.027 | K35: 26 | L35: 46185 | M35: =TEXT(L35,"aaa") -> 금 | N35: 변경지점
A36: 34 | B36: 12)마개미천 | C36: 마개미천 | D36: 양주시 덕계동 169-17 | E36: 2 | G36: 1.4 | H36: 2.9 | I36: 1.035 | J36: 0.025 | K36: 38 | L36: 46185 | M36: =TEXT(L36,"aaa") -> 금 | N36: 신규지점
A37: 35 | B37: 13)회암천 | C37: 회암천_중 | D37: 양주시 옥정동로 율정초교 앞 | E37: 3.4 | G37: 3.5 | H37: 14.4 | I37: 10.134 | J37: 0.077 | K37: 33 | L37: 46185 | M37: =TEXT(L37,"aaa") -> 금
A38: 36 | B38: 14)청담천 | C38: 청담천 | D38: 양주시 고암동 211-1 | E38: 3.6 | G38: 2.2 | H38: 9.3 | I38: 3.045 | J38: 0.05 | K38: 36 | L38: 46185 | M38: =TEXT(L38,"aaa") -> 금
A39: 37 | B39: 15)상패천 | C39: 상패천 | D39: 동두천시 상패동 307-7 인근 (강변교 아래) (신천 합류 전) | E39: 5.3 | G39: 5.6 | H39: 12.8 | I39: 0.678 | J39: 0.069 | K39: 29 | L39: 46183 | M39: =TEXT(L39,"aaa") -> 수

Sheet 202605
A1: 2026년 5월 한탄강 수계 수질조사 결과
A2: 연번 | B2: 하천명 | C2: 시료번호 | D2: 주 소 | E2: TOC | F2: COD | G2: BOD | H2: SS | I2: T-N | J2: T-P | K2: 색도 | L2: 시료채취일 | M2: 요일
A3: 1 | B3: 1)한탄강 | C3: 한탄강1 | D3: 포천시 창수면 운산리 영로교 아래 | E3: 1.9 | F3: 3.7 | G3: 0.7 | H3: 17.5 | I3: 5.179 | J3: 0.109 | K3: 14 | L3: 46161 | M3: =TEXT(L3,"aaa") -> 화
A4: 2 | C4: 한탄강 연1 | D4: 연천군 전곡읍 신답리 1(영평천 합류전) | E4: 2.9 | G4: 2.3 | H4: 10.5 | I4: 2.592 | J4: 0.031 | K4: 19 | L4: 46148 | M4: =TEXT(L4,"aaa") -> 수
A5: 3 | C5: 한탄강 연2 | D5: 연천군 청산면 궁평리 561-1(영평천 합류후) | E5: 3 | G5: 2.4 | H5: 19.1 | I5: 3.007 | J5: 0.037 | K5: 22 | L5: 46148 | M5: =TEXT(L5,"aaa") -> 수
A6: 4 | C6: 한탄강 연4 | D6: 연천군 전곡읍 전곡리 681-2(세월교)_색도 목표지점 | E6: 3.2 | G6: 3.3 | H6: 12.9 | I6: 2.917 | J6: 0.041 | K6: 24 | L6: 46148 | M6: =TEXT(L6,"aaa") -> 수
A7: 5 | B7: 2)포천천 | C7: 포천천1 | D7: 포천시 소흘읍 무봉리 이동교리교 (포천천 상류,부인터사거리 뒤) | E7: 3.5 | G7: 1.2 | H7: 12.6 | I7: 1.93 | J7: 0.138 | K7: 44 | L7: 46161 | M7: =TEXT(L7,"aaa") -> 화
A8: 6 | C8: 포천천2 | D8: 포천시 신읍동 한내교 아래(실제 가스충전소 뒤 / 중류) | E8: 3.8 | F8: 7.3 | G8: 3 | H8: 16 | I8: 1.807 | J8: 0.139 | K8: 47 | L8: 46161 | M8: =TEXT(L8,"aaa") -> 화
A9: 7 | C9: 포천천3 | D9: 포천시 영중면 거사3리 농본교(포천천 하류) | E9: 4 | G9: 2.8 | H9: 13 | I9: 1.941 | J9: 0.15 | K9: 42 | L9: 46161 | M9: =TEXT(L9,"aaa") -> 화
A10: 8 | B10: 3)금현천 | C10: 금현천 | D10: 포천시 가산면 마산리 금현천교 아래(세창아파트 뒤) | E10: 3.3 | G10: 2.2 | H10: 1.8 | I10: 4.937 | J10: 0.04 | K10: 53 | L10: 46161 | M10: =TEXT(L10,"aaa") -> 화
A11: 9 | B11: 4)송우천 | C11: 송우천 | D11: 포천시 송우리 641-92(송우교 아래) | E11: 3.3 | G11: 1.2 | H11: 2.5 | I11: 4.996 | J11: 0.04 | K11: 42 | L11: 46161 | M11: =TEXT(L11,"aaa") -> 화
A12: 10 | B12: 5)영평천 | C12: 영평천1 | D12: 포천시 이동면 노곡리 낭유대교 아래(영평천 상류) | E12: 2.3 | F12: 4.3 | G12: 2.9 | H12: 5.9 | I12: 3.931 | J12: 0.038 | K12: 31 | L12: 46161 | M12: =TEXT(L12,"aaa") -> 화
A13: 11 | C13: 영평천2 | D13: 포천시 영중면 성동리 와룡교 아래(수입천 합류 후) | E13: 2.2 | G13: 0.8 | H13: 5.3 | I13: 4.14 | J13: 0.041 | K13: 24 | L13: 46161 | M13: =TEXT(L13,"aaa") -> 화
A14: 12 | C14: 영평천3 | D14: 포천시 영중면 영송리 영평교 아래(포천천 합류 후) | E14: 2.1 | G14: 1.4 | H14: 6.4 | I14: 4.031 | J14: 0.04 | K14: 33 | L14: 46161 | M14: =TEXT(L14,"aaa") -> 화
A15: 13 | C15: 영평천4 | D15: 포천시 창수면 오가리 오가교 아래(외북천 합류 후) | E15: 2.3 | G15: 0.9 | H15: 7.5 | I15: 3.933 | J15: 0.04 | K15: 30 | L15: 46161 | M15: =TEXT(L15,"aaa") -> 화
A16: 14 | C16: 영평천5 | D16: 포천시 창수면 고소성리 백의교(포천-연천 경계 / 영평천 하류) | E16: 1.9 | G16: 0.5 | H16: 14.3 | I16: 5.043 | J16: 0.102 | K16: 18 | L16: 46161 | M16: =TEXT(L16,"aaa") -> 화
A17: 15 | B17: 6)외북천 | C17: 외북천2 | D17: 포천시 영중면 영송리 통일교 아래(외북천 중류) | E17: 4.9 | G17: 5.1 | H17: 7.9 | I17: 25.6 | J17: 0.057 | K17: 80 | L17: 46161 | M17: =TEXT(L17,"aaa") -> 화
A18: 16 | C18: 외북천3 | D18: 포천시 영중면 영송리 두엄바이오 앞 (외북천 하류) | E18: 5.2 | G18: 5.8 | H18: 6.7 | I18: 26.038 | J18: 0.06 | K18: 82 | L18: 46161 | M18: =TEXT(L18,"aaa") -> 화
A19: 17 | B19: 7)수입천 | C19: 수입천 | D19: 포천시 일동면 사직리 1390-5(일이동처리장 입구) | E19: 1.8 | F19: 3.5 | G19: 0.6 | H19: 7.9 | I19: 4.933 | J19: 0.098 | K19: 13 | L19: 46161 | M19: =TEXT(L19,"aaa") -> 화
A20: 18 | B20: 8)신천 | C20: 신천1 | D20: 양주시 백석읍 오산리 137-2(신천-오산리_방성천 합류 전) | E20: 4 | G20: 3.6 | H20: 20.2 | I20: 2.911 | J20: 0.11 | K20: 33 | L20: 46156 | M20: =TEXT(L20,"aaa") -> 목
A21: 19 | C21: 신천5 | D21: 양주시 광적면 가납리 710(신천-우고천 합류 후) | E21: 4.6 | G21: 4.8 | H21: 12.2 | I21: 21.18 | J21: 0.2 | K21: 30 | L21: 46156 | M21: =TEXT(L21,"aaa") -> 목
A22: 20 | C22: 신천중류 | D22: 양주시 남면 상수리 104-39(입암천 합류 전) | E22: 6.8 | G22: 8 | H22: 18.8 | I22: 6.278 | J22: 0.106 | K22: 34 | L22: 46156 | M22: =TEXT(L22,"aaa") -> 목
A23: 21 | C23: 신천9 | D23: 양주시 은현면 운암리 60-15(은현교) | E23: 5.9 | G23: 6 | H23: 38 | I23: 6.173 | J23: 0.021 | K23: 164 | L23: 46156 | M23: =TEXT(L23,"aaa") -> 목
A24: 22 | C24: 용암교 | D24: 양주시 은현면 용암리 241-1(구 세월교) | E24: 6.7 | F24: 10.1 | G24: 4.7 | H24: 14.6 | I24: 4.89 | J24: 0.073 | K24: 41 | L24: 46156 | M24: =TEXT(L24,"aaa") -> 목
A25: 23 | C25: 신천11 | D25: 양주시 은현면 용암리 240-1(위생환경사업소앞) | E25: 6.1 | G25: 6.2 | H25: 11.2 | I25: 5.289 | J25: 0.06 | K25: 33 | L25: 46156 | M25: =TEXT(L25,"aaa") -> 목
A26: 24 | C26: 신천13 | D26: 동두천시 송내동 651-3(현대아이파크 앞) | E26: 5.5 | G26: 6.1 | H26: 28.8 | I26: 4.898 | J26: 0.128 | K26: 52 | L26: 46149 | M26: =TEXT(L26,"aaa") -> 목
A27: 25 | C27: 신천15 | D27: 동두천시 보산동 429-48 인근 진검다리 | E27: 6.4 | G27: 2.7 | H27: 22.8 | I27: 8.268 | J27: 0.194 | K27: 44 | L27: 46149 | M27: =TEXT(L27,"aaa") -> 목
A28: 26 | C28: 신천17 | D28: 동두천시 하봉암동 340-1 인근 | E28: 7.1 | G28: 3.9 | H28: 5.8 | I28: 6.644 | J28: 0.213 | K28: 122 | L28: 46149 | M28: =TEXT(L28,"aaa") -> 목
A29: 27 | C29: 신천17-2 | D29: 동두천시 하봉암동 327-1(하봉암교) | E29: 6.1 | G29: 4.7 | H29: 18 | I29: 7.214 | J29: 0.184 | K29: 59 | L29: 46149 | M29: =TEXT(L29,"aaa") -> 목
A30: 28 | C30: 신천18-1 | D30: 연천군 청산면 초성리 426, 초성교(시군경계) | E30: 5.9 | G30: 6 | H30: 16.8 | I30: 8.387 | J30: 0.107 | K30: 59 | L30: 46148 | M30: =TEXT(L30,"aaa") -> 수
A31: 29 | C31: 신천18 | D31: 연천군 청산면 초성리 142-5(신천교) | E31: 5.6 | G31: 4.8 | H31: 15.8 | I31: 7.688 | J31: 0.099 | K31: 37 | L31: 46148 | M31: =TEXT(L31,"aaa") -> 수
A32: 30 | C32: 신천20 | D32: 연천군 청산면 초성리 306-5(대전교) | E32: 5.4 | G32: 4.4 | H32: 13 | I32: 6.682 | J32: 0.077 | K32: 37 | L32: 46148 | M32: =TEXT(L32,"aaa") -> 수
A33: 31 | B33: 9)능안천 | C33: 능안천 | D33: 양주시 백석읍 방성리 205-12 | E33: 11 | G33: 6.1 | H33: 10.2 | I33: 112.056 | J33: 0.124 | K33: 47 | L33: 46156 | M33: =TEXT(L33,"aaa") -> 목
A34: 32 | B34: 10)효촌천 | C34: 효촌천 | D34: 양주시 남면 상수리 264 | E34: 13 | G34: 8.1 | H34: 31.6 | I34: 6.255 | J34: 0.086 | K34: 32 | L34: 46156 | M34: =TEXT(L34,"aaa") -> 목
A35: 33 | B35: 11)덕계천 | C35: 덕계천-하 | D35: 양주시 회정동 317-4 | E35: 2.7 | G35: 2.8 | H35: 2.4 | I35: 1.833 | J35: 0.049 | K35: 23 | L35: 46156 | M35: =TEXT(L35,"aaa") -> 목 | N35: 변경지점
A36: 34 | B36: 12)마개미천 | C36: 마개미천 | D36: 양주시 덕계동 169-17 | E36: 5.8 | G36: 5.5 | H36: 7 | I36: 2.286 | J36: 0.034 | K36: 29 | L36: 46156 | M36: =TEXT(L36,"aaa") -> 목 | N36: 신규지점
A37: 35 | B37: 13)회암천 | C37: 회암천_중 | D37: 양주시 옥정동로 율정초교 앞 | E37: 4.8 | G37: 5.2 | H37: 24.8 | I37: 10.832 | J37: 0.106 | K37: 42 | L37: 46156 | M37: =TEXT(L37,"aaa") -> 목
A38: 36 | B38: 14)청담천 | C38: 청담천 | D38: 양주시 고암동 211-1 | E38: 3.6 | G38: 3.8 | H38: 17 | I38: 2.36 | J38: 0.044 | K38: 14 | L38: 46156 | M38: =TEXT(L38,"aaa") -> 목
A39: 37 | B39: 15)상패천 | C39: 상패천 | D39: 동두천시 상패동 307-7 인근 (강변교 아래) (신천 합류 전) | E39: 20.1 | G39: 24.2 | H39: 15.6 | I39: 8.003 | J39: 0.186 | K39: 33 | L39: 46149 | M39: =TEXT(L39,"aaa") -> 목

Sheet 202604
A1: 2026년 4월 한탄강 수계 수질조사 결과
A2: 연번 | B2: 하천명 | C2: 시료번호 | D2: 주 소 | E2: TOC | F2: COD | G2: BOD | H2: SS | I2: T-N | J2: T-P | K2: 색도 | L2: 시료채취일 | M2: 요일
A3: 1 | B3: 1)한탄강 | C3: 한탄강1 | D3: 포천시 창수면 운산리 영로교 아래 | E3: 1.8 | F3: 3.5 | G3: 0.5 | H3: 3.9 | I3: 3.698 | J3: 0.031 | K3: 12 | L3: 46126 | M3: =TEXT(L3,"aaa") -> 화
A4: 2 | C4: 한탄강 연1 | D4: 연천군 전곡읍 신답리 1(영평천 합류전) | E4: 2.8 | G4: 2 | H4: 7 | I4: 2.271 | J4: 0.046 | K4: 18 | L4: 46120 | M4: =TEXT(L4,"aaa") -> 수
A5: 3 | C5: 한탄강 연2 | D5: 연천군 청산면 궁평리 561-1(영평천 합류후) | E5: 3.1 | G5: 2.1 | H5: 8 | I5: 2.953 | J5: 0.051 | K5: 20 | L5: 46120 | M5: =TEXT(L5,"aaa") -> 수
A6: 4 | C6: 한탄강 연4 | D6: 연천군 전곡읍 전곡리 681-2(세월교)_색도 목표지점 | E6: 5 | G6: 3.1 | H6: 8.8 | I6: 4.436 | J6: 0.064 | K6: 26 | L6: 46120 | M6: =TEXT(L6,"aaa") -> 수
A7: 5 | B7: 2)포천천 | C7: 포천천1 | D7: 포천시 소흘읍 무봉리 이동교리교 (포천천 상류,부인터사거리 뒤) | E7: 2.3 | G7: 0.8 | H7: 1.9 | I7: 1.342 | J7: 0.039 | K7: 15 | L7: 46126 | M7: =TEXT(L7,"aaa") -> 화
A8: 6 | C8: 포천천2 | D8: 포천시 신읍동 한내교 아래(실제 가스충전소 뒤 / 중류) | E8: 2.4 | F8: 4.8 | G8: 0.7 | H8: 2.4 | I8: 1.317 | J8: 0.04 | K8: 11 | L8: 46126 | M8: =TEXT(L8,"aaa") -> 화
A9: 7 | C9: 포천천3 | D9: 포천시 영중면 거사3리 농본교(포천천 하류) | E9: 5 | G9: 1.8 | H9: 1.9 | I9: 5.225 | J9: 0.068 | K9: 35 | L9: 46126 | M9: =TEXT(L9,"aaa") -> 화
A10: 8 | B10: 3)금현천 | C10: 금현천 | D10: 포천시 가산면 마산리 금현천교 아래(세창아파트 뒤) | E10: 4.5 | G10: 1.2 | H10: 1.3 | I10: 5.35 | J10: 0.253 | K10: 34 | L10: 46126 | M10: =TEXT(L10,"aaa") -> 화
A11: 9 | B11: 4)송우천 | C11: 송우천 | D11: 포천시 송우리 641-92(송우교 아래) | E11: 4.5 | G11: 1.5 | H11: 1.5 | I11: 5.335 | J11: 0.253 | K11: 33 | L11: 46126 | M11: =TEXT(L11,"aaa") -> 화
A12: 10 | B12: 5)영평천 | C12: 영평천1 | D12: 포천시 이동면 노곡리 낭유대교 아래(영평천 상류) | E12: 2 | F12: 3.9 | G12: 0.6 | H12: 1 | I12: 3.727 | J12: 0.039 | K12: 12 | L12: 46126 | M12: =TEXT(L12,"aaa") -> 화
A13: 11 | C13: 영평천2 | D13: 포천시 영중면 성동리 와룡교 아래(수입천 합류 후) | E13: 1.7 | G13: 0.5 | H13: 1.2 | I13: 3.785 | J13: 0.033 | K13: 13 | L13: 46126 | M13: =TEXT(L13,"aaa") -> 화
A14: 12 | C14: 영평천3 | D14: 포천시 영중면 영송리 영평교 아래(포천천 합류 후) | E14: 2.2 | G14: 0.5 | H14: 0.9 | I14: 3.739 | J14: 0.034 | K14: 15 | L14: 46126 | M14: =TEXT(L14,"aaa") -> 화
A15: 13 | C15: 영평천4 | D15: 포천시 창수면 오가리 오가교 아래(외북천 합류 후) | E15: 2.2 | G15: 0.7 | H15: 1.1 | I15: 3.698 | J15: 0.035 | K15: 12 | L15: 46126 | M15: =TEXT(L15,"aaa") -> 화
A16: 14 | C16: 영평천5 | D16: 포천시 창수면 고소성리 백의교(포천-연천 경계 / 영평천 하류) | E16: 2.2 | G16: 0.6 | H16: 0.8 | I16: 3.702 | J16: 0.036 | K16: 10 | L16: 46126 | M16: =TEXT(L16,"aaa") -> 화
A17: 15 | B17: 6)외북천 | C17: 외북천2 | D17: 포천시 영중면 영송리 통일교 아래(외북천 중류) | E17: 4 | G17: 2.3 | H17: 1.5 | I17: 14.988 | J17: 0.069 | K17: 31 | L17: 46126 | M17: =TEXT(L17,"aaa") -> 화
A18: 16 | C18: 외북천3 | D18: 포천시 영중면 영송리 두엄바이오 앞 (외북천 하류) | E18: 4 | G18: 2.3 | H18: 1.9 | I18: 14.773 | J18: 0.067 | K18: 32 | L18: 46126 | M18: =TEXT(L18,"aaa") -> 화
A19: 17 | B19: 7)수입천 | C19: 수입천 | D19: 포천시 일동면 사직리 1390-5(일이동처리장 입구) | E19: 5 | F19: 9.4 | G19: 2.1 | H19: 1.6 | I19: 5.061 | J19: 0.068 | K19: 34 | L19: 46126 | M19: =TEXT(L19,"aaa") -> 화
A20: 18 | B20: 8)신천 | C20: 신천1 | D20: 양주시 백석읍 오산리 137-2(신천-오산리_방성천 합류 전) | E20: 2.3 | G20: 1.9 | H20: 14.4 | I20: 6.732 | J20: 0.08 | K20: 6 | L20: 46120 | M20: =TEXT(L20,"aaa") -> 수
A21: 19 | C21: 신천5 | D21: 양주시 광적면 가납리 710(신천-우고천 합류 후) | E21: 3.2 | G21: 3.1 | H21: 6.9 | I21: 10.423 | J21: 0.13 | K21: 8 | L21: 46120 | M21: =TEXT(L21,"aaa") -> 수
A22: 20 | C22: 신천중류 | D22: 양주시 남면 상수리 104-39(입암천 합류 전) | E22: 7.5 | G22: 5.7 | H22: 20 | I22: 7.094 | J22: 0.127 | K22: 22 | L22: 46120 | M22: =TEXT(L22,"aaa") -> 수
A23: 21 | C23: 신천9 | D23: 양주시 은현면 운암리 60-15(은현교) | E23: 7.3 | G23: 3.2 | H23: 10.4 | I23: 7.276 | J23: 0.128 | K23: 25 | L23: 46120 | M23: =TEXT(L23,"aaa") -> 수
A24: 22 | C24: 용암교 | D24: 양주시 은현면 용암리 241-1(구 세월교) | E24: 4.9 | F24: 9.8 | G24: 4.7 | H24: 22.4 | I24: 6.321 | J24: 0.107 | K24: 41 | L24: 46120 | M24: =TEXT(L24,"aaa") -> 수
A25: 23 | C25: 신천11 | D25: 양주시 은현면 용암리 240-1(위생환경사업소앞) | E25: 7.9 | G25: 4 | H25: 20.4 | I25: 6.302 | J25: 0.106 | K25: 57 | L25: 46120 | M25: =TEXT(L25,"aaa") -> 수
A26: 24 | C26: 신천13 | D26: 동두천시 송내동 651-3(현대아이파크 앞) | E26: 5.6 | G26: 4.9 | H26: 7.2 | I26: 6.359 | J26: 0.08 | K26: 20 | L26: 46120 | M26: =TEXT(L26,"aaa") -> 수
A27: 25 | C27: 신천15 | D27: 동두천시 보산동 429-48 인근 진검다리 | E27: 8.1 | G27: 6.8 | H27: 8.8 | I27: 9.285 | J27: 0.104 | K27: 38 | L27: 46120 | M27: =TEXT(L27,"aaa") -> 수
A28: 26 | C28: 신천17 | D28: 동두천시 하봉암동 340-1 인근 | E28: 10.2 | G28: 2.8 | H28: 10 | I28: 8.106 | J28: 0.149 | K28: 130 | L28: 46120 | M28: =TEXT(L28,"aaa") -> 수
A29: 27 | C29: 신천17-2 | D29: 동두천시 하봉암동 327-1(하봉암교) | E29: 9.7 | G29: 2.5 | H29: 11.6 | I29: 8.811 | J29: 0.108 | K29: 83 | L29: 46120 | M29: =TEXT(L29,"aaa") -> 수
A30: 28 | C30: 신천18-1 | D30: 연천군 청산면 초성리 426, 초성교(시군경계) | E30: 7.8 | G30: 9.6 | H30: 12 | I30: 10.175 | J30: 0.091 | K30: 59 | L30: 46120 | M30: =TEXT(L30,"aaa") -> 수
A31: 29 | C31: 신천18 | D31: 연천군 청산면 초성리 142-5(신천교) | E31: 7.5 | G31: 4.6 | H31: 11.2 | I31: 9.639 | J31: 0.104 | K31: 56 | L31: 46120 | M31: =TEXT(L31,"aaa") -> 수
A32: 30 | C32: 신천20 | D32: 연천군 청산면 초성리 306-5(대전교) | E32: 7.3 | G32: 3 | H32: 8.4 | I32: 8.133 | J32: 0.079 | K32: 54 | L32: 46120 | M32: =TEXT(L32,"aaa") -> 수
A33: 31 | B33: 9)능안천 | C33: 능안천 | D33: 양주시 백석읍 방성리 205-12 | E33: 22.2 | G33: 4.2 | H33: 6.2 | I33: 152.947 | J33: 0.201 | K33: 72 | L33: 46120 | M33: =TEXT(L33,"aaa") -> 수
A34: 32 | B34: 10)효촌천 | C34: 효촌천 | D34: 양주시 남면 상수리 264 | E34: 15.3 | G34: 4.1 | H34: 5.6 | I34: 5.04 | J34: 0.221 | K34: 39 | L34: 46120 | M34: =TEXT(L34,"aaa") -> 수
A35: 33 | B35: 11)덕계천 | C35: 덕계천-하 | D35: 양주시 회정동 317-4 | E35: 19.3 | G35: 2.7 | H35: 9.1 | I35: 1.723 | J35: 0.028 | K35: 19 | L35: 46120 | M35: =TEXT(L35,"aaa") -> 수 | N35: 변경지점
A36: 34 | B36: 12)마개미천 | C36: 마개미천 | D36: 양주시 덕계동 169-17 | E36: 8.4 | G36: 5.7 | H36: 7.6 | I36: 3.336 | J36: 0.094 | K36: 7 | L36: 46120 | M36: =TEXT(L36,"aaa") -> 수 | N36: 신규지점
A37: 35 | B37: 13)회암천 | C37: 회암천_중 | D37: 양주시 옥정동로 율정초교 앞 | E37: 5.4 | G37: 2.1 | H37: 15.5 | I37: 10.973 | J37: 0.051 | K37: 40 | L37: 46120 | M37: =TEXT(L37,"aaa") -> 수
A38: 36 | B38: 14)청담천 | C38: 청담천 | D38: 양주시 고암동 211-1 | E38: 2.9 | G38: 1.4 | H38: 124.8 | I38: 3.023 | J38: 0.139 | K38: 16 | L38: 46120 | M38: =TEXT(L38,"aaa") -> 수
A39: 37 | B39: 15)상패천 | C39: 상패천 | D39: 동두천시 상패동 307-7 인근 (강변교 아래) (신천 합류 전) | E39: 7.4 | G39: 9.2 | H39: 10.2 | I39: 4.033 | J39: 0.196 | K39: 24 | L39: 46120 | M39: =TEXT(L39,"aaa") -> 수

Sheet 202603
A1: 2026년 3월 한탄강 수계 수질조사 결과
A2: 연번 | B2: 하천명 | C2: 시료번호 | D2: 주 소 | E2: TOC | F2: COD | G2: BOD | H2: SS | I2: T-N | J2: T-P | K2: 색도 | L2: 시료채취일 | M2: 요일
A3: 1 | B3: 1)한탄강 | C3: 한탄강1 | D3: 포천시 창수면 운산리 영로교 아래 | E3: 3.8 | F3: 5.1 | G3: 2.8 | H3: 2.4 | I3: 6.015 | J3: 0.036 | K3: 20 | L3: 46105 | M3: =TEXT(L3,"aaa") -> 화
A4: 2 | C4: 한탄강 연1 | D4: 연천군 전곡읍 신답리 1(영평천 합류전) | E4: 2.1 | G4: 1.8 | H4: 2.9 | I4: 2.253 | J4: 0.018 | K4: 8 | L4: 46092 | M4: =TEXT(L4,"aaa") -> 수
A5: 3 | C5: 한탄강 연2 | D5: 연천군 청산면 궁평리 561-1(영평천 합류후) | E5: 2.4 | G5: 1.9 | H5: 2.8 | I5: 3.486 | J5: 0.021 | K5: 11 | L5: 46092 | M5: =TEXT(L5,"aaa") -> 수
A6: 4 | C6: 한탄강 연4 | D6: 연천군 전곡읍 전곡리 681-2(세월교)_색도 목표지점 | E6: 2.8 | G6: 1.9 | H6: 2.5 | I6: 4.079 | J6: 0.027 | K6: 17 | L6: 46092 | M6: =TEXT(L6,"aaa") -> 수
A7: 5 | B7: 2)포천천 | C7: 포천천1 | D7: 포천시 소흘읍 무봉리 이동교리교 (포천천 상류,부인터사거리 뒤) | E7: 3.7 | G7: 2.7 | H7: 2.5 | I7: 6.124 | J7: 0.037 | K7: 14 | L7: 46105 | M7: =TEXT(L7,"aaa") -> 화
A8: 6 | C8: 포천천2 | D8: 포천시 신읍동 한내교 아래(실제 가스충전소 뒤 / 중류) | E8: 3.9 | F8: 5.5 | G8: 2.5 | H8: 3.3 | I8: 6.078 | J8: 0.034 | K8: 18 | L8: 46105 | M8: =TEXT(L8,"aaa") -> 화
A9: 7 | C9: 포천천3 | D9: 포천시 영중면 거사3리 농본교(포천천 하류) | E9: 3.9 | G9: 2.9 | H9: 2.8 | I9: 6.377 | J9: 0.036 | K9: 24 | L9: 46105 | M9: =TEXT(L9,"aaa") -> 화
A10: 8 | B10: 3)금현천 | C10: 금현천 | D10: 포천시 가산면 마산리 금현천교 아래(세창아파트 뒤) | E10: 5.9 | G10: 3.4 | H10: 8.8 | I10: 6.661 | J10: 0.05 | K10: 36 | L10: 46105 | M10: =TEXT(L10,"aaa") -> 화
A11: 9 | B11: 4)송우천 | C11: 송우천 | D11: 포천시 송우리 641-92(송우교 아래) | E11: 5.8 | G11: 2.3 | H11: 3.3 | I11: 6.648 | J11: 0.05 | K11: 37 | L11: 46105 | M11: =TEXT(L11,"aaa") -> 화
A12: 10 | B12: 5)영평천 | C12: 영평천1 | D12: 포천시 이동면 노곡리 낭유대교 아래(영평천 상류) | E12: 2.4 | F12: 2.9 | G12: 2.2 | H12: 2 | I12: 4.635 | J12: 0.021 | K12: 15 | L12: 46105 | M12: =TEXT(L12,"aaa") -> 화
A13: 11 | C13: 영평천2 | D13: 포천시 영중면 성동리 와룡교 아래(수입천 합류 후) | E13: 2.3 | G13: 2 | H13: 1.8 | I13: 4.678 | J13: 0.022 | K13: 18 | L13: 46105 | M13: =TEXT(L13,"aaa") -> 화
A14: 12 | C14: 영평천3 | D14: 포천시 영중면 영송리 영평교 아래(포천천 합류 후) | E14: 2.4 | G14: 2 | H14: 2.7 | I14: 4.751 | J14: 0.035 | K14: 9 | L14: 46105 | M14: =TEXT(L14,"aaa") -> 화
A15: 13 | C15: 영평천4 | D15: 포천시 창수면 오가리 오가교 아래(외북천 합류 후) | E15: 2.4 | G15: 1.6 | H15: 1.8 | I15: 4.473 | J15: 0.021 | K15: 12 | L15: 46105 | M15: =TEXT(L15,"aaa") -> 화
A16: 14 | C16: 영평천5 | D16: 포천시 창수면 고소성리 백의교(포천-연천 경계 / 영평천 하류) | E16: 2.2 | G16: 2.1 | H16: 1.7 | I16: 4.718 | J16: 0.031 | K16: 17 | L16: 46105 | M16: =TEXT(L16,"aaa") -> 화
A17: 15 | B17: 6)외북천 | C17: 외북천2 | D17: 포천시 영중면 영송리 통일교 아래(외북천 중류) | E17: 5.9 | G17: 5.1 | H17: 5.2 | I17: 26.718 | J17: 0.088 | K17: 35 | L17: 46105 | M17: =TEXT(L17,"aaa") -> 화
A18: 16 | C18: 외북천3 | D18: 포천시 영중면 영송리 두엄바이오 앞 (외북천 하류) | E18: 5.9 | G18: 5 | H18: 5.4 | I18: 29.178 | J18: 0.091 | K18: 35 | L18: 46105 | M18: =TEXT(L18,"aaa") -> 화
A19: 17 | B19: 7)수입천 | C19: 수입천 | D19: 포천시 일동면 사직리 1390-5(일이동처리장 입구) | E19: 5.6 | F19: 9.2 | G19: 2.1 | H19: 3.3 | I19: 6.561 | J19: 0.046 | K19: 32 | L19: 46105 | M19: =TEXT(L19,"aaa") -> 화
A20: 18 | B20: 8)신천 | C20: 신천1 | D20: 양주시 백석읍 오산리 137-2(신천-오산리_방성천 합류 전) | E20: 2.75 | G20: 2.2 | H20: 5.6 | I20: 5.782 | J20: 0.086 | K20: 17 | L20: 46091 | M20: =TEXT(L20,"aaa") -> 화
A21: 19 | C21: 신천5 | D21: 양주시 광적면 가납리 710(신천-우고천 합류 후) | E21: 4.67 | G21: 3.2 | H21: 4.1 | I21: 9.054 | J21: 0.093 | K21: 9 | L21: 46091 | M21: =TEXT(L21,"aaa") -> 화
A22: 20 | C22: 신천중류 | D22: 양주시 남면 상수리 104-39(입암천 합류 전) | E22: 5.57 | G22: 3.6 | H22: 4.6 | I22: 6.991 | J22: 0.108 | K22: 22 | L22: 46091 | M22: =TEXT(L22,"aaa") -> 화
A23: 21 | C23: 신천9 | D23: 양주시 은현면 운암리 60-15(은현교) | E23: 5.65 | G23: 3.9 | H23: 5.6 | I23: 7.295 | J23: 0.097 | K23: 16 | L23: 46091 | M23: =TEXT(L23,"aaa") -> 화
A24: 22 | C24: 용암교 | D24: 양주시 은현면 용암리 241-1(구 세월교) | E24: 5.79 | F24: 7.7 | G24: 2.9 | H24: 5.3 | I24: 7.001 | J24: 0.062 | K24: 23 | L24: 46091 | M24: =TEXT(L24,"aaa") -> 화
A25: 23 | C25: 신천11 | D25: 양주시 은현면 용암리 240-1(위생환경사업소앞) | E25: 5.48 | G25: 2.9 | H25: 4.8 | I25: 7.141 | J25: 0.07 | K25: 24 | L25: 46091 | M25: =TEXT(L25,"aaa") -> 화
A26: 24 | C26: 신천13 | D26: 동두천시 송내동 651-3(현대아이파크 앞) | E26: 4.92 | G26: 4.1 | H26: 6 | I26: 8.257 | J26: 0.063 | K26: 23 | L26: 46093 | M26: =TEXT(L26,"aaa") -> 목
A27: 25 | C27: 신천15 | D27: 동두천시 보산동 429-48 인근 진검다리 | E27: 7.02 | G27: 5 | H27: 6.6 | I27: 10.286 | J27: 0.092 | K27: 41 | L27: 46093 | M27: =TEXT(L27,"aaa") -> 목
A28: 26 | C28: 신천17 | D28: 동두천시 하봉암동 340-1 인근 | E28: 10.81 | G28: 4.2 | H28: 8.6 | I28: 7.081 | J28: 0.134 | K28: 142 | L28: 46093 | M28: =TEXT(L28,"aaa") -> 목
A29: 27 | C29: 신천17-2 | D29: 동두천시 하봉암동 327-1(하봉암교) | E29: 8.67 | G29: 5.6 | H29: 11.8 | I29: 8.539 | J29: 0.095 | K29: 89 | L29: 46093 | M29: =TEXT(L29,"aaa") -> 목
A30: 28 | C30: 신천18-1 | D30: 연천군 청산면 초성리 426, 초성교(시군경계) | E30: 8.6 | G30: 4.9 | H30: 9.2 | I30: 11.012 | J30: 0.118 | K30: 50 | L30: 46092 | M30: =TEXT(L30,"aaa") -> 수
A31: 29 | C31: 신천18 | D31: 연천군 청산면 초성리 142-5(신천교) | E31: 8.6 | G31: 6.8 | H31: 11 | I31: 10.437 | J31: 0.122 | K31: 51 | L31: 46092 | M31: =TEXT(L31,"aaa") -> 수
A32: 30 | C32: 신천20 | D32: 연천군 청산면 초성리 306-5(대전교) | E32: 7.3 | G32: 4 | H32: 8 | I32: 10.711 | J32: 0.091 | K32: 49 | L32: 46092 | M32: =TEXT(L32,"aaa") -> 수
A33: 31 | B33: 9)능안천 | C33: 능안천 | D33: 양주시 백석읍 방성리 205-12 | E33: 10.55 | G33: 3.3 | H33: 3.9 | I33: 45.867 | J33: 0.102 | K33: 23 | L33: 46091 | M33: =TEXT(L33,"aaa") -> 화
A34: 32 | B34: 10)효촌천 | C34: 효촌천 | D34: 양주시 남면 상수리 264 | E34: 11.51 | G34: 6.6 | H34: 7.2 | I34: 5.591 | J34: 0.126 | K34: 32 | L34: 46091 | M34: =TEXT(L34,"aaa") -> 화
A35: 33 | B35: 11)덕계천 | C35: 덕계천-하 | D35: 양주시 회정동 317-4 | E35: 2.7 | G35: 2.2 | H35: 1.2 | I35: 3.766 | J35: 0.023 | K35: 17 | L35: 46091 | M35: =TEXT(L35,"aaa") -> 화 | N35: 변경지점
A36: 34 | B36: 12)마개미천 | C36: 마개미천 | D36: 양주시 덕계동 169-17 | E36: 4.76 | G36: 3.8 | H36: 6.2 | I36: 4.138 | J36: 0.152 | K36: 26 | L36: 46091 | M36: =TEXT(L36,"aaa") -> 화 | N36: 신규지점
A37: 35 | B37: 13)회암천 | C37: 회암천_중 | D37: 양주시 옥정동로 율정초교 앞 | E37: 5.43 | G37: 2.8 | H37: 2.9 | I37: 9.442 | J37: 0.039 | K37: 31 | L37: 46091 | M37: =TEXT(L37,"aaa") -> 화
A38: 36 | B38: 14)청담천 | C38: 청담천 | D38: 양주시 고암동 211-1 | E38: 3.7 | G38: 2.2 | H38: 186.4 | I38: 3.566 | J38: 0.115 | K38: 20 | L38: 46091 | M38: =TEXT(L38,"aaa") -> 화
A39: 37 | B39: 15)상패천 | C39: 상패천 | D39: 동두천시 상패동 307-7 인근 (강변교 아래) (신천 합류 전) | E39: 4.89 | G39: 4.1 | H39: 8.4 | I39: 3.594 | J39: 0.184 | K39: 21 | L39: 46093 | M39: =TEXT(L39,"aaa") -> 목

Sheet 202602
A1: 2026년 2월 한탄강 수계 수질조사 결과
A2: 연번 | B2: 하천명 | C2: 시료번호 | D2: 주 소 | E2: TOC | F2: COD | G2: BOD | H2: SS | I2: T-N | J2: T-P | K2: 색도 | L2: 시료채취일 | M2: 요일
A3: 1 | B3: 1)한탄강 | C3: 한탄강1 | D3: 포천시 창수면 운산리 영로교 아래 | E3: 11.9 | F3: 15.7 | G3: 2.4 | H3: 4.8 | I3: 8.39 | J3: 0.073 | K3: 16 | L3: 46076 | M3: =TEXT(L3,"aaa") -> 월
A4: 2 | C4: 한탄강 연1 | D4: 연천군 전곡읍 신답리 1(영평천 합류전) | E4: 1.8 | G4: 0.8 | H4: 1.3 | I4: 2.733 | J4: 0.025 | K4: 18 | L4: 46063 | M4: =TEXT(L4,"aaa") -> 화
A5: 3 | C5: 한탄강 연2 | D5: 연천군 청산면 궁평리 561-1(영평천 합류후) | E5: 2.2 | G5: 0.9 | H5: 1.5 | I5: 3.941 | J5: 0.027 | K5: 18 | L5: 46063 | M5: =TEXT(L5,"aaa") -> 화
A6: 4 | C6: 한탄강 연4 | D6: 연천군 전곡읍 전곡리 681-2(세월교)_색도 목표지점 | E6: 4.1 | G6: 1.3 | H6: 2.7 | I6: 8.214 | J6: 0.051 | K6: 23 | L6: 46063 | M6: =TEXT(L6,"aaa") -> 화
A7: 5 | B7: 2)포천천 | C7: 포천천1 | D7: 포천시 소흘읍 무봉리 이동교리교 (포천천 상류,부인터사거리 뒤) | E7: 3.3 | G7: 1.9 | H7: 1.5 | I7: 7.857 | J7: 0.043 | K7: 17 | L7: 46076 | M7: =TEXT(L7,"aaa") -> 월
A8: 6 | C8: 포천천2 | D8: 포천시 신읍동 한내교 아래(실제 가스충전소 뒤 / 중류) | E8: 3.3 | F8: 4.4 | G8: 2.1 | H8: 1.6 | I8: 7.733 | J8: 0.05 | K8: 17 | L8: 46076 | M8: =TEXT(L8,"aaa") -> 월
A9: 7 | C9: 포천천3 | D9: 포천시 영중면 거사3리 농본교(포천천 하류) | E9: 3.4 | G9: 2.2 | H9: 1.5 | I9: 7.667 | J9: 0.045 | K9: 19 | L9: 46076 | M9: =TEXT(L9,"aaa") -> 월
A10: 8 | B10: 3)금현천 | C10: 금현천 | D10: 포천시 가산면 마산리 금현천교 아래(세창아파트 뒤) | E10: 6.3 | G10: 2.2 | H10: 4.3 | I10: 9.478 | J10: 0.038 | K10: 38 | L10: 46076 | M10: =TEXT(L10,"aaa") -> 월
A11: 9 | B11: 4)송우천 | C11: 송우천 | D11: 포천시 송우리 641-92(송우교 아래) | E11: 5.1 | G11: 2.1 | H11: 6 | I11: 9.504 | J11: 0.039 | K11: 36 | L11: 46076 | M11: =TEXT(L11,"aaa") -> 월
A12: 10 | B12: 5)영평천 | C12: 영평천1 | D12: 포천시 이동면 노곡리 낭유대교 아래(영평천 상류) | E12: 2.1 | F12: 4 | G12: 1.2 | H12: 0.8 | I12: 7.806 | J12: 0.047 | K12: 14 | L12: 46076 | M12: =TEXT(L12,"aaa") -> 월
A13: 11 | C13: 영평천2 | D13: 포천시 영중면 성동리 와룡교 아래(수입천 합류 후) | E13: 2 | G13: 1.1 | H13: 1.2 | I13: 7.83 | J13: 0.044 | K13: 19 | L13: 46076 | M13: =TEXT(L13,"aaa") -> 월
A14: 12 | C14: 영평천3 | D14: 포천시 영중면 영송리 영평교 아래(포천천 합류 후) | E14: 2 | G14: 1 | H14: 0.9 | I14: 7.872 | J14: 0.042 | K14: 17 | L14: 46076 | M14: =TEXT(L14,"aaa") -> 월
A15: 13 | C15: 영평천4 | D15: 포천시 창수면 오가리 오가교 아래(외북천 합류 후) | E15: 2 | G15: 1.4 | H15: 0.9 | I15: 7.697 | J15: 0.042 | K15: 16 | L15: 46076 | M15: =TEXT(L15,"aaa") -> 월
A16: 14 | C16: 영평천5 | D16: 포천시 창수면 고소성리 백의교(포천-연천 경계 / 영평천 하류) | E16: 2 | G16: 1.3 | H16: 0.9 | I16: 7.535 | J16: 0.046 | K16: 16 | L16: 46076 | M16: =TEXT(L16,"aaa") -> 월
A17: 15 | B17: 6)외북천 | C17: 외북천2 | D17: 포천시 영중면 영송리 통일교 아래(외북천 중류) | E17: 7.1 | G17: 2.8 | H17: 1.6 | I17: 36.276 | J17: 0.059 | K17: 74 | L17: 46076 | M17: =TEXT(L17,"aaa") -> 월
A18: 16 | C18: 외북천3 | D18: 포천시 영중면 영송리 두엄바이오 앞 (외북천 하류) | E18: 7.1 | G18: 3.2 | H18: 2 | I18: 35.668 | J18: 0.06 | K18: 73 | L18: 46076 | M18: =TEXT(L18,"aaa") -> 월
A19: 17 | B19: 7)수입천 | C19: 수입천 | D19: 포천시 일동면 사직리 1390-5(일이동처리장 입구) | E19: 4.7 | F19: 7.1 | G19: 1.7 | H19: 1 | I19: 8.241 | J19: 0.078 | K19: 16 | L19: 46076 | M19: =TEXT(L19,"aaa") -> 월
A20: 18 | B20: 8)신천 | C20: 신천1 | D20: 양주시 백석읍 오산리 137-2(신천-오산리_방성천 합류 전) | E20: 4.4 | G20: 2.3 | H20: 2.5 | I20: 6.869 | J20: 0.093 | K20: 9 | L20: 46076 | M20: =TEXT(L20,"aaa") -> 월
A21: 19 | C21: 신천5 | D21: 양주시 광적면 가납리 710(신천-우고천 합류 후) | E21: 3.2 | G21: 2.3 | H21: 4 | I21: 10.139 | J21: 0.118 | K21: 12 | L21: 46076 | M21: =TEXT(L21,"aaa") -> 월
A22: 20 | C22: 신천중류 | D22: 양주시 남면 상수리 104-39(입암천 합류 전) | E22: 3.9 | G22: 2.5 | H22: 2.7 | I22: 7.994 | J22: 0.081 | K22: 14 | L22: 46076 | M22: =TEXT(L22,"aaa") -> 월
A23: 21 | C23: 신천9 | D23: 양주시 은현면 운암리 60-15(은현교) | E23: 4.9 | G23: 2.4 | H23: 2.6 | I23: 9.462 | J23: 0.064 | K23: 21 | L23: 46076 | M23: =TEXT(L23,"aaa") -> 월
A24: 22 | C24: 용암교 | D24: 양주시 은현면 용암리 241-1(구 세월교) | E24: 3.2 | F24: 6.4 | G24: 2.1 | H24: 9.2 | I24: 8.044 | J24: 0.064 | K24: 13 | L24: 46076 | M24: =TEXT(L24,"aaa") -> 월
A25: 23 | C25: 신천11 | D25: 양주시 은현면 용암리 240-1(위생환경사업소앞) | E25: 5.1 | G25: 2.1 | H25: 8.2 | I25: 8.13 | J25: 0.056 | K25: 14 | L25: 46076 | M25: =TEXT(L25,"aaa") -> 월
A26: 24 | C26: 신천13 | D26: 동두천시 송내동 651-3(현대아이파크 앞) | E26: 4.5 | G26: 2.1 | H26: 2.4 | I26: 9.326 | J26: 0.06 | K26: 22 | L26: 46062 | M26: =TEXT(L26,"aaa") -> 월
A27: 25 | C27: 신천15 | D27: 동두천시 보산동 429-48 인근 진검다리 | E27: 6.3 | G27: 3.9 | H27: 4 | I27: 12.374 | J27: 0.09 | K27: 27 | L27: 46062 | M27: =TEXT(L27,"aaa") -> 월
A28: 26 | C28: 신천17 | D28: 동두천시 하봉암동 340-1 인근 | E28: 7.5 | G28: 2.5 | H28: 7 | I28: 15.389 | J28: 0.103 | K28: 64 | L28: 46062 | M28: =TEXT(L28,"aaa") -> 월
A29: 27 | C29: 신천17-2 | D29: 동두천시 하봉암동 327-1(하봉암교) | E29: 6.9 | G29: 3 | H29: 4 | I29: 13.373 | J29: 0.082 | K29: 52 | L29: 46062 | M29: =TEXT(L29,"aaa") -> 월
A30: 28 | C30: 신천18-1 | D30: 연천군 청산면 초성리 426, 초성교(시군경계) | E30: 8.5 | G30: 2.7 | H30: 8.6 | I30: 14.195 | J30: 0.142 | K30: 45 | L30: 46063 | M30: =TEXT(L30,"aaa") -> 화
A31: 29 | C31: 신천18 | D31: 연천군 청산면 초성리 142-5(신천교) | E31: 8.2 | G31: 2.5 | H31: 8.8 | I31: 13.594 | J31: 0.131 | K31: 46 | L31: 46063 | M31: =TEXT(L31,"aaa") -> 화
A32: 30 | C32: 신천20 | D32: 연천군 청산면 초성리 306-5(대전교) | E32: 6.5 | G32: 2.5 | H32: 5.6 | I32: 13.078 | J32: 0.106 | K32: 42 | L32: 46063 | M32: =TEXT(L32,"aaa") -> 화
A33: 31 | B33: 9)능안천 | C33: 능안천 | D33: 양주시 백석읍 방성리 205-12 | E33: 6.7 | G33: 2.7 | H33: 6.8 | I33: 25.174 | J33: 0.052 | K33: 13 | L33: 46076 | M33: =TEXT(L33,"aaa") -> 월
A34: 32 | B34: 10)효촌천 | C34: 효촌천 | D34: 양주시 남면 상수리 264 | E34: 4.7 | G34: 3.8 | H34: 8 | I34: 6.517 | J34: 0.109 | K34: 13 | L34: 46076 | M34: =TEXT(L34,"aaa") -> 월
A35: 33 | B35: 11)덕계천 | C35: 덕계천-하 | D35: 양주시 회정동 317-4 | E35: 3.5 | G35: 2.3 | H35: 1.1 | I35: 3.405 | J35: 0.028 | K35: 8 | L35: 46076 | M35: =TEXT(L35,"aaa") -> 월 | N35: 변경지점
A36: 34 | B36: 12)마개미천 | C36: 마개미천 | D36: 양주시 덕계동 169-17 | E36: 5.6 | G36: 4 | H36: 4.8 | I36: 3.98 | J36: 0.152 | K36: 10 | L36: 46076 | M36: =TEXT(L36,"aaa") -> 월 | N36: 신규지점
A37: 35 | B37: 13)회암천 | C37: 회암천_중 | D37: 양주시 옥정동로 율정초교 앞 | E37: 5 | G37: 2.3 | H37: 0.9 | I37: 12.12 | J37: 0.017 | K37: 15 | L37: 46076 | M37: =TEXT(L37,"aaa") -> 월
A38: 36 | B38: 14)청담천 | C38: 청담천 | D38: 양주시 고암동 211-1 | E38: 2.7 | G38: 1.7 | H38: 12 | I38: 3.604 | J38: 0.061 | K38: 8 | L38: 46076 | M38: =TEXT(L38,"aaa") -> 월
A39: 37 | B39: 15)상패천 | C39: 상패천 | D39: 동두천시 상패동 307-7 인근 (강변교 아래) (신천 합류 전) | E39: 3.7 | G39: 2.8 | H39: 3.6 | I39: 7.968 | J39: 0.073 | K39: 18 | L39: 46062 | M39: =TEXT(L39,"aaa") -> 월

Sheet 202601
A1: 2026년 1월 한탄강 수계 수질조사 결과
A2: 연번 | B2: 하천명 | C2: 시료번호 | D2: 주 소 | E2: TOC | F2: COD | G2: BOD | H2: SS | I2: T-N | J2: T-P | K2: 색도 | L2: 시료채취일 | M2: 요일
A3: 1 | B3: 1)한탄강 | C3: 한탄강1 | D3: 포천시 창수면 운산리 영로교 아래 | E3: 2.5 | F3: 5 | G3: 1.5 | H3: 2.9 | I3: 9.636 | J3: 0.169 | K3: 24 | L3: 46048 | M3: =TEXT(L3,"aaa") -> 월
A4: 2 | C4: 한탄강 연1 | D4: 연천군 전곡읍 신답리 1(영평천 합류전) | E4: 1.9 | G4: 1 | H4: 1.5 | I4: 3.047 | J4: 0.011 | K4: 8 | L4: 46029 | M4: =TEXT(L4,"aaa") -> 수
A5: 3 | C5: 한탄강 연2 | D5: 연천군 청산면 궁평리 561-1(영평천 합류후) | E5: 2.3 | G5: 1.2 | H5: 0.9 | I5: 4.723 | J5: 0.014 | K5: 6 | L5: 46029 | M5: =TEXT(L5,"aaa") -> 수
A6: 4 | C6: 한탄강 연4 | D6: 연천군 전곡읍 전곡리 681-2(세월교)_색도 목표지점 | E6: 2.3 | G6: 1.5 | H6: 0.8 | I6: 4.959 | J6: 0.019 | K6: 10 | L6: 46029 | M6: =TEXT(L6,"aaa") -> 수
A7: 5 | B7: 2)포천천 | C7: 포천천1 | D7: 포천시 소흘읍 무봉리 이동교리교 (포천천 상류,부인터사거리 뒤) | E7: 2.3 | G7: 1.3 | H7: 0.9 | I7: 10.672 | J7: 0.055 | K7: 10 | L7: 46048 | M7: =TEXT(L7,"aaa") -> 월
A8: 6 | C8: 포천천2 | D8: 포천시 신읍동 한내교 아래(실제 가스충전소 뒤 / 중류) | E8: 2.5 | F8: 3.1 | G8: 1.5 | H8: 0.8 | I8: 10.502 | J8: 0.06 | K8: 8 | L8: 46048 | M8: =TEXT(L8,"aaa") -> 월
A9: 7 | C9: 포천천3 | D9: 포천시 영중면 거사3리 농본교(포천천 하류) | E9: 2.4 | G9: 1.7 | H9: 1.2 | I9: 10.544 | J9: 0.058 | K9: 24 | L9: 46048 | M9: =TEXT(L9,"aaa") -> 월
A10: 8 | B10: 3)금현천 | C10: 금현천 | D10: 포천시 가산면 마산리 금현천교 아래(세창아파트 뒤) | E10: 4.3 | G10: 2.3 | H10: 4.7 | I10: 10.691 | J10: 0.03 | K10: 19 | L10: 46048 | M10: =TEXT(L10,"aaa") -> 월
A11: 9 | B11: 4)송우천 | C11: 송우천 | D11: 포천시 송우리 641-92(송우교 아래) | E11: 4.2 | G11: 2.8 | H11: 4.5 | I11: 10.587 | J11: 0.028 | K11: 18 | L11: 46048 | M11: =TEXT(L11,"aaa") -> 월
A12: 10 | B12: 5)영평천 | C12: 영평천1 | D12: 포천시 이동면 노곡리 낭유대교 아래(영평천 상류) | E12: 2.7 | F12: 3.1 | G12: 1.7 | H12: 1.3 | I12: 8.635 | J12: 0.086 | K12: 12 | L12: 46048 | M12: =TEXT(L12,"aaa") -> 월
A13: 11 | C13: 영평천2 | D13: 포천시 영중면 성동리 와룡교 아래(수입천 합류 후) | E13: 2.5 | G13: 1.4 | H13: 1.3 | I13: 8.783 | J13: 0.088 | K13: 23 | L13: 46048 | M13: =TEXT(L13,"aaa") -> 월
A14: 12 | C14: 영평천3 | D14: 포천시 영중면 영송리 영평교 아래(포천천 합류 후) | E14: 2.5 | G14: 1.9 | H14: 1.6 | I14: 9.009 | J14: 0.084 | K14: 14 | L14: 46048 | M14: =TEXT(L14,"aaa") -> 월
A15: 13 | C15: 영평천4 | D15: 포천시 창수면 오가리 오가교 아래(외북천 합류 후) | E15: 2.5 | G15: 1.4 | H15: 1.5 | I15: 8.735 | J15: 0.085 | K15: 15 | L15: 46048 | M15: =TEXT(L15,"aaa") -> 월
A16: 14 | C16: 영평천5 | D16: 포천시 창수면 고소성리 백의교(포천-연천 경계 / 영평천 하류) | E16: 2.5 | G16: 2 | H16: 1.3 | I16: 8.827 | J16: 0.085 | K16: 15 | L16: 46029 | M16: =TEXT(L16,"aaa") -> 수
A17: 15 | B17: 6)외북천 | C17: 외북천2 | D17: 포천시 영중면 영송리 통일교 아래(외북천 중류) | E17: 4.1 | G17: 2 | H17: 1.6 | I17: 17.022 | J17: 0.038 | K17: 28 | L17: 46048 | M17: =TEXT(L17,"aaa") -> 월
A18: 16 | C18: 외북천3 | D18: 포천시 영중면 영송리 두엄바이오 앞 (외북천 하류) | E18: 3.9 | G18: 2.4 | H18: 1.6 | I18: 17.319 | J18: 0.034 | K18: 31 | L18: 46048 | M18: =TEXT(L18,"aaa") -> 월
A19: 17 | B19: 7)수입천 | C19: 수입천 | D19: 포천시 일동면 사직리 1390-5(일이동처리장 입구) | E19: 2.2 | F19: 3.5 | G19: 1.6 | H19: 3.3 | I19: 9.335 | J19: 0.169 | K19: 8 | L19: 46048 | M19: =TEXT(L19,"aaa") -> 월
A20: 18 | B20: 8)신천 | C20: 신천1 | D20: 양주시 백석읍 오산리 137-2(신천-오산리_방성천 합류 전) | E20: 13.5 | G20: 9.1 | H20: 43.6 | I20: 7.753 | J20: 0.156 | K20: 7 | L20: 46029 | M20: =TEXT(L20,"aaa") -> 수
A21: 19 | C21: 신천5 | D21: 양주시 광적면 가납리 710(신천-우고천 합류 후) | E21: 2.3 | G21: 1.3 | H21: 3.6 | I21: 9.158 | J21: 0.07 | K21: 11 | L21: 46029 | M21: =TEXT(L21,"aaa") -> 수
A22: 20 | C22: 신천중류 | D22: 양주시 남면 상수리 104-39(입암천 합류 전) | E22: 7 | G22: 4.7 | H22: 21 | I22: 9.06 | J22: 0.095 | K22: 55 | L22: 46029 | M22: =TEXT(L22,"aaa") -> 수
A23: 21 | C23: 신천9 | D23: 양주시 은현면 운암리 60-15(은현교) | E23: 4.9 | G23: 3.6 | H23: 12.9 | I23: 9.912 | J23: 0.055 | K23: 24 | L23: 46029 | M23: =TEXT(L23,"aaa") -> 수
A24: 22 | C24: 용암교 | D24: 양주시 은현면 용암리 241-1(구 세월교) | E24: 4.6 | F24: 5.1 | G24: 3 | H24: 6.7 | I24: 8.674 | J24: 0.084 | K24: 15 | L24: 46029 | M24: =TEXT(L24,"aaa") -> 수
A25: 23 | C25: 신천11 | D25: 양주시 은현면 용암리 240-1(위생환경사업소앞) | E25: 4.4 | G25: 2.8 | H25: 3.5 | I25: 8.547 | J25: 0.08 | K25: 19 | L25: 46029 | M25: =TEXT(L25,"aaa") -> 수
A26: 24 | C26: 신천13 | D26: 동두천시 송내동 651-3(현대아이파크 앞) | E26: 3.52 | G26: 2.3 | H26: 2.8 | I26: 8.788 | J26: 0.05 | K26: 9 | L26: 46028 | M26: =TEXT(L26,"aaa") -> 화
A27: 25 | C27: 신천15 | D27: 동두천시 보산동 429-48 인근 진검다리 | E27: 6.29 | G27: 5 | H27: 4 | I27: 11.069 | J27: 0.075 | K27: 19 | L27: 46028 | M27: =TEXT(L27,"aaa") -> 화
A28: 26 | C28: 신천17 | D28: 동두천시 하봉암동 340-1 인근 | E28: 8.97 | G28: 4.1 | H28: 6 | I28: 11.299 | J28: 0.104 | K28: 66 | L28: 46028 | M28: =TEXT(L28,"aaa") -> 화
A29: 27 | C29: 신천17-2 | D29: 동두천시 하봉암동 327-1(하봉암교) | E29: 8.06 | G29: 6.2 | H29: 8.6 | I29: 11.963 | J29: 0.117 | K29: 44 | L29: 46028 | M29: =TEXT(L29,"aaa") -> 화
A30: 28 | C30: 신천18-1 | D30: 연천군 청산면 초성리 426, 초성교(시군경계) | E30: 9.1 | G30: 6.1 | H30: 7.6 | I30: 10.145 | J30: 0.118 | K30: 30 | L30: 46029 | M30: =TEXT(L30,"aaa") -> 수
A31: 29 | C31: 신천18 | D31: 연천군 청산면 초성리 142-5(신천교) | E31: 8.9 | G31: 6.5 | H31: 9 | I31: 10.207 | J31: 0.123 | K31: 31 | L31: 46029 | M31: =TEXT(L31,"aaa") -> 수
A32: 30 | C32: 신천20 | D32: 연천군 청산면 초성리 306-5(대전교) | E32: 8.2 | G32: 4.2 | H32: 5.8 | I32: 9.53 | J32: 0.102 | K32: 36 | L32: 46029 | M32: =TEXT(L32,"aaa") -> 수
A33: 31 | B33: 9)능안천 | C33: 능안천 | D33: 양주시 백석읍 방성리 205-12 | E33: 25.4 | G33: 18.4 | H33: 11.2 | I33: 72.337 | J33: 0.142 | K33: 45 | L33: 46029 | M33: =TEXT(L33,"aaa") -> 수
A34: 32 | B34: 10)효촌천 | C34: 효촌천 | D34: 양주시 남면 상수리 264 | E34: 18.4 | G34: 12.3 | H34: 28.8 | I34: 9.286 | J34: 0.172 | K34: 49 | L34: 46029 | M34: =TEXT(L34,"aaa") -> 수
A35: 33 | B35: 11)덕계천 | C35: 덕계천-하 | D35: 양주시 회정동 317-4 | E35: 4 | G35: 2.1 | H35: 3.7 | I35: 4.418 | J35: 0.087 | K35: 10 | L35: 46029 | M35: =TEXT(L35,"aaa") -> 수 | N35: 변경지점
A36: 34 | B36: 12)마개미천 | C36: 마개미천 | D36: 양주시 덕계동 169-17 | E36: 14.9 | G36: 10.2 | H36: 16 | I36: 3.673 | J36: 0.072 | K36: 8 | L36: 46029 | M36: =TEXT(L36,"aaa") -> 수 | N36: 신규지점
A37: 35 | B37: 13)회암천 | C37: 회암천_중 | D37: 양주시 옥정동로 율정초교 앞 | E37: 6.1 | G37: 4.1 | H37: 3.5 | I37: 10.98 | J37: 0.049 | K37: 28 | L37: 46029 | M37: =TEXT(L37,"aaa") -> 수
A38: 36 | B38: 14)청담천 | C38: 청담천 | D38: 양주시 고암동 211-1 | E38: 2.7 | G38: 1.7 | H38: 7 | I38: 4.32 | J38: 0.036 | K38: 7 | L38: 46029 | M38: =TEXT(L38,"aaa") -> 수
A39: 37 | B39: 15)상패천 | C39: 상패천 | D39: 동두천시 상패동 307-7 인근 (강변교 아래) (신천 합류 전) | E39: 3.15 | G39: 2.7 | H39: 1.3 | I39: 7.876 | J39: 0.048 | K39: 7 | L39: 46028 | M39: =TEXT(L39,"aaa") -> 화

Sheet 26년 월별 TOC현황
A1: 2026년 월별 TOC 현황
A2: 연번 | B2: 하천명 | C2: 시료번호 | D2: 주 소 | E2: 1월 | F2: 2월 | G2: 3월 | H2: 4월 | I2: 5월 | J2: 6월 | K2: 7월 | L2: 8월 | M2: 9월 | N2: 10월 | O2: 11월 | P2: 12월 | Q2: 최대 | R2: 최소 | S2: 평균 | T2: 편차 | U2: 생활환경 기준등급
A3: 2 | B3: 1)한탄강 | C3: 한탄강1 | D3: 포천시 창수면 운산리 영로교 아래 | E3: ='202601'!E3 -> 2.5 | F3: ='202602'!E3 -> 11.9 | G3: ='202603'!E3 -> 3.8 | H3: ='202604'!E3 -> 1.8 | I3: ='202605'!E3 -> 1.9 | J3: ='202606'!E3 -> 2.9 | K3: ='202607'!E3 -> 2.93 | L3: ='202608'!E3 -> 2.4 | M3: ='202609'!E3 -> 3.92 | Q3: =MAX(E3:P3) -> 11.9 | R3: =MIN(E3:P3) -> 1.8 | S3: =AVERAGE(E3:P3) -> 3.7833333 | T3: =STDEV(E3:P3) -> 3.1314693 | U3: =IF(S3<=2, "매우좋음", IF(S3<=3, "좋음", IF(S3<=4, "약간좋음", IF(S3<=5, "보통", IF(S3<=6, "약간나쁨", IF(S3<=8, "나쁨", "매우나쁨")))))) -> 약간좋음
A4: 3 | C4: 한탄강 연1 | D4: 연천군 전곡읍 신답리 1(영평천 합류전) | E4: ='202601'!E4 -> 1.9 | F4: ='202602'!E4 -> 1.8 | G4: ='202603'!E4 -> 2.1 | H4: ='202604'!E4 -> 2.8 | I4: ='202605'!E4 -> 2.9 | J4: ='202606'!E4 -> 2.8 | K4: ='202607'!E4 -> 1.93 | L4: ='202608'!E4 -> 2.1 | M4: ='202609'!E4 -> 1.9 | Q4: =MAX(E4:P4) -> 2.9 | R4: =MIN(E4:P4) -> 1.8 | S4: =AVERAGE(E4:P4) -> 2.2477778 | T4: =STDEV(E4:P4) -> 0.45032704 | U4: =IF(S4<=2, "매우좋음", IF(S4<=3, "좋음", IF(S4<=4, "약간좋음", IF(S4<=5, "보통", IF(S4<=6, "약간나쁨", IF(S4<=8, "나쁨", "매우나쁨")))))) -> 좋음
A5: 4 | C5: 한탄강 연2 | D5: 연천군 청산면 궁평리 561-1(영평천 합류후) | E5: ='202601'!E5 -> 2.3 | F5: ='202602'!E5 -> 2.2 | G5: ='202603'!E5 -> 2.4 | H5: ='202604'!E5 -> 3.1 | I5: ='202605'!E5 -> 3 | J5: ='202606'!E5 -> 2.9 | K5: ='202607'!E5 -> 1.87 | L5: ='202608'!E5 -> 2.7 | M5: ='202609'!E5 -> 2 | Q5: =MAX(E5:P5) -> 3.1 | R5: =MIN(E5:P5) -> 1.87 | S5: =AVERAGE(E5:P5) -> 2.4966667 | T5: =STDEV(E5:P5) -> 0.44676616 | U5: =IF(S5<=2, "매우좋음", IF(S5<=3, "좋음", IF(S5<=4, "약간좋음", IF(S5<=5, "보통", IF(S5<=6, "약간나쁨", IF(S5<=8, "나쁨", "매우나쁨")))))) -> 좋음
A6: 8 | C6: 한탄강 연4 | D6: 연천군 전곡읍 전곡리 681-2(세월교)_색도 목표지점 | E6: ='202601'!E6 -> 2.3 | F6: ='202602'!E6 -> 4.1 | G6: ='202603'!E6 -> 2.8 | H6: ='202604'!E6 -> 5 | I6: ='202605'!E6 -> 3.2 | J6: ='202606'!E6 -> 3.5 | K6: ='202607'!E6 -> 1.83 | L6: ='202608'!E6 -> 3 | M6: ='202609'!E6 -> 2.4 | Q6: =MAX(E6:P6) -> 5 | R6: =MIN(E6:P6) -> 1.83 | S6: =AVERAGE(E6:P6) -> 3.1255556 | T6: =STDEV(E6:P6) -> 0.97577035 | U6: =IF(S6<=2, "매우좋음", IF(S6<=3, "좋음", IF(S6<=4, "약간좋음", IF(S6<=5, "보통", IF(S6<=6, "약간나쁨", IF(S6<=8, "나쁨", "매우나쁨")))))) -> 약간좋음
